Workbook

Sheet Cómo usar
A1: MI FINANCIERA: control de préstamos
A3: Columnas con encabezado VERDE y fondo crema: las llenas tú (texto azul). Encabezado GRIS: se calculan solas, no las toques.
A5: 1. Préstamos: una fila por préstamo (N°, cliente, teléfono, capital, tipo de interés, valor, meses). Lo demás se calcula.
A6: Tipo de interés: % → porcentaje sobre el capital total (1000*16%/2mes)
A7: Fijo total → monto fijo de interés por todo el préstamo
A8: Fijo por mes → monto fijo cada mes (ej. un refinanciamiento con interés simbólico de 25/mes)
A9: 2. Cuotas: una fila por cuota. Pon el N° de préstamo, el N° de cuota, el tipo y la fecha límite. Capital e interés se calculan solos.
A10: Cuando te paguen: cambia Estado a 'Pagado' y escribe la fecha de pago.
A11: Si pagan SOLO INTERÉS: agrega una fila con Tipo = 'Solo interés' (N° de cuota vacío) y márcala Pagado;
A12: luego corre un mes la Fecha límite de todas sus cuotas pendientes (3/3 +1 = 4/4).
A13: Tip: usa el filtro de la columna 'Situación' para ver solo Atrasado / Este mes.
A14: 3. Resumen: capital en la calle, por cobrar del mes, cobrado, ganancia y totales por mes.
... A20: Los 3 préstamos cargados son ejemplos ficticios: bórralos (filas de Préstamos y Cuotas) y escribe los tuyos.

Sheet Resumen
A1: Resumen
A2: Hoy | B2: =TODAY()
A4: Capital en la calle | B4: =SUMIFS(Cuotas!$F$2:$F$601,Cuotas!$I$2:$I$601,"Pendiente")
A5: Interés por cobrar | B5: =SUMIFS(Cuotas!$G$2:$G$601,Cuotas!$I$2:$I$601,"Pendiente")
A6: Por cobrar este mes (incluye atrasados) | B6: =SUMIFS(Cuotas!$H$2:$H$601,Cuotas!$I$2:$I$601,"Pendiente",Cuotas!$E$2:$E$601,"<="&EOMONTH(TODAY(),0))
A7: Cobrado este mes | B7: =SUMIFS(Cuotas!$H$2:$H$601,Cuotas!$I$2:$I$601,"Pagado",Cuotas!$J$2:$J$601,">"&EOMONTH(TODAY(),-1),Cuotas!$J$2:$J$601,"<="&EOMONTH(TODAY(),0))
A8: Ganancia (interés) este mes | B8: =SUMIFS(Cuotas!$G$2:$G$601,Cuotas!$I$2:$I$601,"Pagado",Cuotas!$J$2:$J$601,">"&EOMONTH(TODAY(),-1),Cuotas!$J$2:$J$601,"<="&EOMONTH(TODAY(),0))
A9: Cuotas atrasadas | B9: =COUNTIFS(Cuotas!$I$2:$I$601,"Pendiente",Cuotas!$E$2:$E$601,"<"&TODAY())
A10: Monto atrasado | B10: =SUMIFS(Cuotas!$H$2:$H$601,Cuotas!$I$2:$I$601,"Pendiente",Cuotas!$E$2:$E$601,"<"&TODAY())
A11: Ganancia total (interés cobrado) | B11: =SUMIFS(Cuotas!$G$2:$G$601,Cuotas!$I$2:$I$601,"Pagado")
A12: Préstamos activos | B12: =COUNTIF('Préstamos'!$R$2:$R$101,"Al día")+COUNTIF('Préstamos'!$R$2:$R$101,"Atrasado")
A14: Año | B14: 2026
A15: Mes | B15: Por cobrar (pendiente) | C15: Capital cobrado | D15: Interés ganado | E15: Total cobrado
A16: Enero | B16: =SUMIFS(Cuotas!$H$2:$H$601,Cuotas!$I$2:$I$601,"Pendiente",Cuotas!$E$2:$E$601,">="&DATE($B$14,1,1),Cuotas!$E$2:$E$601,"<="&EOMONTH(DATE($B$14,1,1),0)) | C16: =SUMIFS(Cuotas!$F$2:$F$601,Cuotas!$I$2:$I$601,"Pagado",Cuotas!$J$2:$J$601,">="&DATE($B$14,1,1),Cuotas!$J$2:$J$601,"<="&EOMONTH(DATE($B$14,1,1),0)) | D16: =SUMIFS(Cuotas!$G$2:$G$601,Cuotas!$I$2:$I$601,"Pagado",Cuotas!$J$2:$J$601,">="&DATE($B$14,1,1),Cuotas!$J$2:$J$601,"<="&EOMONTH(DATE($B$14,1,1),0)) | E16: =C16+D16
A17: Febrero | B17: =SUMIFS(Cuotas!$H$2:$H$601,Cuotas!$I$2:$I$601,"Pendiente",Cuotas!$E$2:$E$601,">="&DATE($B$14,2,1),Cuotas!$E$2:$E$601,"<="&EOMONTH(DATE($B$14,2,1),0)) | C17: =SUMIFS(Cuotas!$F$2:$F$601,Cuotas!$I$2:$I$601,"Pagado",Cuotas!$J$2:$J$601,">="&DATE($B$14,2,1),Cuotas!$J$2:$J$601,"<="&EOMONTH(DATE($B$14,2,1),0)) | D17: =SUMIFS(Cuotas!$G$2:$G$601,Cuotas!$I$2:$I$601,"Pagado",Cuotas!$J$2:$J$601,">="&DATE($B$14,2,1),Cuotas!$J$2:$J$601,"<="&EOMONTH(DATE($B$14,2,1),0)) | E17: =C17+D17
A18: Marzo | B18: =SUMIFS(Cuotas!$H$2:$H$601,Cuotas!$I$2:$I$601,"Pendiente",Cuotas!$E$2:$E$601,">="&DATE($B$14,3,1),Cuotas!$E$2:$E$601,"<="&EOMONTH(DATE($B$14,3,1),0)) | C18: =SUMIFS(Cuotas!$F$2:$F$601,Cuotas!$I$2:$I$601,"Pagado",Cuotas!$J$2:$J$601,">="&DATE($B$14,3,1),Cuotas!$J$2:$J$601,"<="&EOMONTH(DATE($B$14,3,1),0)) | D18: =SUMIFS(Cuotas!$G$2:$G$601,Cuotas!$I$2:$I$601,"Pagado",Cuotas!$J$2:$J$601,">="&DATE($B$14,3,1),Cuotas!$J$2:$J$601,"<="&EOMONTH(DATE($B$14,3,1),0)) | E18: =C18+D18
A19: Abril | B19: =SUMIFS(Cuotas!$H$2:$H$601,Cuotas!$I$2:$I$601,"Pendiente",Cuotas!$E$2:$E$601,">="&DATE($B$14,4,1),Cuotas!$E$2:$E$601,"<="&EOMONTH(DATE($B$14,4,1),0)) | C19: =SUMIFS(Cuotas!$F$2:$F$601,Cuotas!$I$2:$I$601,"Pagado",Cuotas!$J$2:$J$601,">="&DATE($B$14,4,1),Cuotas!$J$2:$J$601,"<="&EOMONTH(DATE($B$14,4,1),0)) | D19: =SUMIFS(Cuotas!$G$2:$G$601,Cuotas!$I$2:$I$601,"Pagado",Cuotas!$J$2:$J$601,">="&DATE($B$14,4,1),Cuotas!$J$2:$J$601,"<="&EOMONTH(DATE($B$14,4,1),0)) | E19: =C19+D19
A20: Mayo | B20: =SUMIFS(Cuotas!$H$2:$H$601,Cuotas!$I$2:$I$601,"Pendiente",Cuotas!$E$2:$E$601,">="&DATE($B$14,5,1),Cuotas!$E$2:$E$601,"<="&EOMONTH(DATE($B$14,5,1),0)) | C20: =SUMIFS(Cuotas!$F$2:$F$601,Cuotas!$I$2:$I$601,"Pagado",Cuotas!$J$2:$J$601,">="&DATE($B$14,5,1),Cuotas!$J$2:$J$601,"<="&EOMONTH(DATE($B$14,5,1),0)) | D20: =SUMIFS(Cuotas!$G$2:$G$601,Cuotas!$I$2:$I$601,"Pagado",Cuotas!$J$2:$J$601,">="&DATE($B$14,5,1),Cuotas!$J$2:$J$601,"<="&EOMONTH(DATE($B$14,5,1),0)) | E20: =C20+D20
A21: Junio | B21: =SUMIFS(Cuotas!$H$2:$H$601,Cuotas!$I$2:$I$601,"Pendiente",Cuotas!$E$2:$E$601,">="&DATE($B$14,6,1),Cuotas!$E$2:$E$601,"<="&EOMONTH(DATE($B$14,6,1),0)) | C21: =SUMIFS(Cuotas!$F$2:$F$601,Cuotas!$I$2:$I$601,"Pagado",Cuotas!$J$2:$J$601,">="&DATE($B$14,6,1),Cuotas!$J$2:$J$601,"<="&EOMONTH(DATE($B$14,6,1),0)) | D21: =SUMIFS(Cuotas!$G$2:$G$601,Cuotas!$I$2:$I$601,"Pagado",Cuotas!$J$2:$J$601,">="&DATE($B$14,6,1),Cuotas!$J$2:$J$601,"<="&EOMONTH(DATE($B$14,6,1),0)) | E21: =C21+D21
A22: Julio | B22: =SUMIFS(Cuotas!$H$2:$H$601,Cuotas!$I$2:$I$601,"Pendiente",Cuotas!$E$2:$E$601,">="&DATE($B$14,7,1),Cuotas!$E$2:$E$601,"<="&EOMONTH(DATE($B$14,7,1),0)) | C22: =SUMIFS(Cuotas!$F$2:$F$601,Cuotas!$I$2:$I$601,"Pagado",Cuotas!$J$2:$J$601,">="&DATE($B$14,7,1),Cuotas!$J$2:$J$601,"<="&EOMONTH(DATE($B$14,7,1),0)) | D22: =SUMIFS(Cuotas!$G$2:$G$601,Cuotas!$I$2:$I$601,"Pagado",Cuotas!$J$2:$J$601,">="&DATE($B$14,7,1),Cuotas!$J$2:$J$601,"<="&EOMONTH(DATE($B$14,7,1),0)) | E22: =C22+D22
A23: Agosto | B23: =SUMIFS(Cuotas!$H$2:$H$601,Cuotas!$I$2:$I$601,"Pendiente",Cuotas!$E$2:$E$601,">="&DATE($B$14,8,1),Cuotas!$E$2:$E$601,"<="&EOMONTH(DATE($B$14,8,1),0)) | C23: =SUMIFS(Cuotas!$F$2:$F$601,Cuotas!$I$2:$I$601,"Pagado",Cuotas!$J$2:$J$601,">="&DATE($B$14,8,1),Cuotas!$J$2:$J$601,"<="&EOMONTH(DATE($B$14,8,1),0)) | D23: =SUMIFS(Cuotas!$G$2:$G$601,Cuotas!$I$2:$I$601,"Pagado",Cuotas!$J$2:$J$601,">="&DATE($B$14,8,1),Cuotas!$J$2:$J$601,"<="&EOMONTH(DATE($B$14,8,1),0)) | E23: =C23+D23
A24: Septiembre | B24: =SUMIFS(Cuotas!$H$2:$H$601,Cuotas!$I$2:$I$601,"Pendiente",Cuotas!$E$2:$E$601,">="&DATE($B$14,9,1),Cuotas!$E$2:$E$601,"<="&EOMONTH(DATE($B$14,9,1),0)) | C24: =SUMIFS(Cuotas!$F$2:$F$601,Cuotas!$I$2:$I$601,"Pagado",Cuotas!$J$2:$J$601,">="&DATE($B$14,9,1),Cuotas!$J$2:$J$601,"<="&EOMONTH(DATE($B$14,9,1),0)) | D24: =SUMIFS(Cuotas!$G$2:$G$601,Cuotas!$I$2:$I$601,"Pagado",Cuotas!$J$2:$J$601,">="&DATE($B$14,9,1),Cuotas!$J$2:$J$601,"<="&EOMONTH(DATE($B$14,9,1),0)) | E24: =C24+D24
A25: Octubre | B25: =SUMIFS(Cuotas!$H$2:$H$601,Cuotas!$I$2:$I$601,"Pendiente",Cuotas!$E$2:$E$601,">="&DATE($B$14,10,1),Cuotas!$E$2:$E$601,"<="&EOMONTH(DATE($B$14,10,1),0)) | C25: =SUMIFS(Cuotas!$F$2:$F$601,Cuotas!$I$2:$I$601,"Pagado",Cuotas!$J$2:$J$601,">="&DATE($B$14,10,1),Cuotas!$J$2:$J$601,"<="&EOMONTH(DATE($B$14,10,1),0)) | D25: =SUMIFS(Cuotas!$G$2:$G$601,Cuotas!$I$2:$I$601,"Pagado",Cuotas!$J$2:$J$601,">="&DATE($B$14,10,1),Cuotas!$J$2:$J$601,"<="&EOMONTH(DATE($B$14,10,1),0)) | E25: =C25+D25
A26: Noviembre | B26: =SUMIFS(Cuotas!$H$2:$H$601,Cuotas!$I$2:$I$601,"Pendiente",Cuotas!$E$2:$E$601,">="&DATE($B$14,11,1),Cuotas!$E$2:$E$601,"<="&EOMONTH(DATE($B$14,11,1),0)) | C26: =SUMIFS(Cuotas!$F$2:$F$601,Cuotas!$I$2:$I$601,"Pagado",Cuotas!$J$2:$J$601,">="&DATE($B$14,11,1),Cuotas!$J$2:$J$601,"<="&EOMONTH(DATE($B$14,11,1),0)) | D26: =SUMIFS(Cuotas!$G$2:$G$601,Cuotas!$I$2:$I$601,"Pagado",Cuotas!$J$2:$J$601,">="&DATE($B$14,11,1),Cuotas!$J$2:$J$601,"<="&EOMONTH(DATE($B$14,11,1),0)) | E26: =C26+D26
A27: Diciembre | B27: =SUMIFS(Cuotas!$H$2:$H$601,Cuotas!$I$2:$I$601,"Pendiente",Cuotas!$E$2:$E$601,">="&DATE($B$14,12,1),Cuotas!$E$2:$E$601,"<="&EOMONTH(DATE($B$14,12,1),0)) | C27: =SUMIFS(Cuotas!$F$2:$F$601,Cuotas!$I$2:$I$601,"Pagado",Cuotas!$J$2:$J$601,">="&DATE($B$14,12,1),Cuotas!$J$2:$J$601,"<="&EOMONTH(DATE($B$14,12,1),0)) | D27: =SUMIFS(Cuotas!$G$2:$G$601,Cuotas!$I$2:$I$601,"Pagado",Cuotas!$J$2:$J$601,">="&DATE($B$14,12,1),Cuotas!$J$2:$J$601,"<="&EOMONTH(DATE($B$14,12,1),0)) | E27: =C27+D27
A28: Total del año | B28: =SUM(B16:B27) | C28: =SUM(C16:C27) | D28: =SUM(D16:D27) | E28: =SUM(E16:E27)

Sheet Préstamos
A1: N° | B1: Cliente | C1: Teléfono | D1: Capital | E1: Tipo de interés | F1: Valor (% o S/) | G1: Meses | H1: Nota | I1: Interés total | J1: Capital por cuota | K1: Interés por cuota | L1: Cuota mensual | M1: Fórmula (como tu nota) | N1: Capital pendiente | O1: Interés cobrado | P1: Próximo vencimiento | Q1: Cuotas pagadas | R1: Estado
A2: 1 | B2: María (ejemplo) | D2: 1000 | E2: % | F2: 16 | G2: 2 | I2: =IF($A2="","",IF(E2="%",D2*F2/100,IF(E2="Fijo por mes",F2*G2,F2))) | J2: =IF($A2="","",ROUNDUP(D2/G2,0)) | K2: =IF($A2="","",ROUNDDOWN(I2/G2,0)) | L2: =IF($A2="","",J2+K2) | M2: =IF($A2="","",IF(E2="%",D2&"*"&F2&"%",IF(E2="Fijo por mes",D2&"cap+"&F2&"int/mes",D2&"cap+"&I2&"int"))&IF(G2>1,IF(E2="Fijo por mes"," x ","/")&G2&"mes","")&" → "&J2&"cap+"&K2&"int="&L2) | N2: =IF($A2="","",SUMIFS(Cuotas!$F$2:$F$601,Cuotas!$A$2:$A$601,$A2,Cuotas!$I$2:$I$601,"Pendiente")) | O2: =IF($A2="","",SUMIFS(Cuotas!$G$2:$G$601,Cuotas!$A$2:$A$601,$A2,Cuotas!$I$2:$I$601,"Pagado")) | P2: =IF($A2="","",IF(COUNTIFS(Cuotas!$A$2:$A$601,$A2,Cuotas!$I$2:$I$601,"Pendiente")=0,"—",_xlfn.MINIFS(Cuotas!$E$2:$E$601,Cuotas!$A$2:$A$601,$A2,Cuotas!$I$2:$I$601,"Pendiente"))) | Q2: =IF($A2="","",COUNTIFS(Cuotas!$A$2:$A$601,$A2,Cuotas!$I$2:$I$601,"Pagado")&"/"&COUNTIFS(Cuotas!$A$2:$A$601,$A2)) | R2: =IF($A2="","",IF(COUNTIFS(Cuotas!$A$2:$A$601,$A2,Cuotas!$I$2:$I$601,"Pendiente")=0,"Terminado",IF(P2<TODAY(),"Atrasado","Al día")))
A3: 2 | B3: Juan (ejemplo) | D3: 2000 | E3: % | F3: 20 | G3: 3 | H3: Pagó solo interés un mes → 3/3 +1 (4/4) | I3: =IF($A3="","",IF(E3="%",D3*F3/100,IF(E3="Fijo por mes",F3*G3,F3))) | J3: =IF($A3="","",ROUNDUP(D3/G3,0)) | K3: =IF($A3="","",ROUNDDOWN(I3/G3,0)) | L3: =IF($A3="","",J3+K3) | M3: =IF($A3="","",IF(E3="%",D3&"*"&F3&"%",IF(E3="Fijo por mes",D3&"cap+"&F3&"int/mes",D3&"cap+"&I3&"int"))&IF(G3>1,IF(E3="Fijo por mes"," x ","/")&G3&"mes","")&" → "&J3&"cap+"&K3&"int="&L3) | N3: =IF($A3="","",SUMIFS(Cuotas!$F$2:$F$601,Cuotas!$A$2:$A$601,$A3,Cuotas!$I$2:$I$601,"Pendiente")) | O3: =IF($A3="","",SUMIFS(Cuotas!$G$2:$G$601,Cuotas!$A$2:$A$601,$A3,Cuotas!$I$2:$I$601,"Pagado")) | P3: =IF($A3="","",IF(COUNTIFS(Cuotas!$A$2:$A$601,$A3,Cuotas!$I$2:$I$601,"Pendiente")=0,"—",_xlfn.MINIFS(Cuotas!$E$2:$E$601,Cuotas!$A$2:$A$601,$A3,Cuotas!$I$2:$I$601,"Pendiente"))) | Q3: =IF($A3="","",COUNTIFS(Cuotas!$A$2:$A$601,$A3,Cuotas!$I$2:$I$601,"Pagado")&"/"&COUNTIFS(Cuotas!$A$2:$A$601,$A3)) | R3: =IF($A3="","",IF(COUNTIFS(Cuotas!$A$2:$A$601,$A3,Cuotas!$I$2:$I$601,"Pendiente")=0,"Terminado",IF(P3<TODAY(),"Atrasado","Al día")))
A4: 3 | B4: Pedro y Rosa (ejemplo) | D4: 1700 | E4: Fijo por mes | F4: 25 | G4: 4 | H4: Refinanciado: 1400cap+500int-200=1700. Interés simbólico 25/mes. | I4: =IF($A4="","",IF(E4="%",D4*F4/100,IF(E4="Fijo por mes",F4*G4,F4))) | J4: =IF($A4="","",ROUNDUP(D4/G4,0)) | K4: =IF($A4="","",ROUNDDOWN(I4/G4,0)) | L4: =IF($A4="","",J4+K4) | M4: =IF($A4="","",IF(E4="%",D4&"*"&F4&"%",IF(E4="Fijo por mes",D4&"cap+"&F4&"int/mes",D4&"cap+"&I4&"int"))&IF(G4>1,IF(E4="Fijo por mes"," x ","/")&G4&"mes","")&" → "&J4&"cap+"&K4&"int="&L4) | N4: =IF($A4="","",SUMIFS(Cuotas!$F$2:$F$601,Cuotas!$A$2:$A$601,$A4,Cuotas!$I$2:$I$601,"Pendiente")) | O4: =IF($A4="","",SUMIFS(Cuotas!$G$2:$G$601,Cuotas!$A$2:$A$601,$A4,Cuotas!$I$2:$I$601,"Pagado")) | P4: =IF($A4="","",IF(COUNTIFS(Cuotas!$A$2:$A$601,$A4,Cuotas!$I$2:$I$601,"Pendiente")=0,"—",_xlfn.MINIFS(Cuotas!$E$2:$E$601,Cuotas!$A$2:$A$601,$A4,Cuotas!$I$2:$I$601,"Pendiente"))) | Q4: =IF($A4="","",COUNTIFS(Cuotas!$A$2:$A$601,$A4,Cuotas!$I$2:$I$601,"Pagado")&"/"&COUNTIFS(Cuotas!$A$2:$A$601,$A4)) | R4: =IF($A4="","",IF(COUNTIFS(Cuotas!$A$2:$A$601,$A4,Cuotas!$I$2:$I$601,"Pendiente")=0,"Terminado",IF(P4<TODAY(),"Atrasado","Al día")))
I5: =IF($A5="","",IF(E5="%",D5*F5/100,IF(E5="Fijo por mes",F5*G5,F5))) | J5: =IF($A5="","",ROUNDUP(D5/G5,0)) | K5: =IF($A5="","",ROUNDDOWN(I5/G5,0)) | L5: =IF($A5="","",J5+K5) | M5: =IF($A5="","",IF(E5="%",D5&"*"&F5&"%",IF(E5="Fijo por mes",D5&"cap+"&F5&"int/mes",D5&"cap+"&I5&"int"))&IF(G5>1,IF(E5="Fijo por mes"," x ","/")&G5&"mes","")&" → "&J5&"cap+"&K5&"int="&L5) | N5: =IF($A5="","",SUMIFS(Cuotas!$F$2:$F$601,Cuotas!$A$2:$A$601,$A5,Cuotas!$I$2:$I$601,"Pendiente")) | O5: =IF($A5="","",SUMIFS(Cuotas!$G$2:$G$601,Cuotas!$A$2:$A$601,$A5,Cuotas!$I$2:$I$601,"Pagado")) | P5: =IF($A5="","",IF(COUNTIFS(Cuotas!$A$2:$A$601,$A5,Cuotas!$I$2:$I$601,"Pendiente")=0,"—",_xlfn.MINIFS(Cuotas!$E$2:$E$601,Cuotas!$A$2:$A$601,$A5,Cuotas!$I$2:$I$601,"Pendiente"))) | Q5: =IF($A5="","",COUNTIFS(Cuotas!$A$2:$A$601,$A5,Cuotas!$I$2:$I$601,"Pagado")&"/"&COUNTIFS(Cuotas!$A$2:$A$601,$A5)) | R5: =IF($A5="","",IF(COUNTIFS(Cuotas!$A$2:$A$601,$A5,Cuotas!$I$2:$I$601,"Pendiente")=0,"Terminado",IF(P5<TODAY(),"Atrasado","Al día")))
I6: =IF($A6="","",IF(E6="%",D6*F6/100,IF(E6="Fijo por mes",F6*G6,F6))) | J6: =IF($A6="","",ROUNDUP(D6/G6,0)) | K6: =IF($A6="","",ROUNDDOWN(I6/G6,0)) | L6: =IF($A6="","",J6+K6) | M6: =IF($A6="","",IF(E6="%",D6&"*"&F6&"%",IF(E6="Fijo por mes",D6&"cap+"&F6&"int/mes",D6&"cap+"&I6&"int"))&IF(G6>1,IF(E6="Fijo por mes"," x ","/")&G6&"mes","")&" → "&J6&"cap+"&K6&"int="&L6) | N6: =IF($A6="","",SUMIFS(Cuotas!$F$2:$F$601,Cuotas!$A$2:$A$601,$A6,Cuotas!$I$2:$I$601,"Pendiente")) | O6: =IF($A6="","",SUMIFS(Cuotas!$G$2:$G$601,Cuotas!$A$2:$A$601,$A6,Cuotas!$I$2:$I$601,"Pagado")) | P6: =IF($A6="","",IF(COUNTIFS(Cuotas!$A$2:$A$601,$A6,Cuotas!$I$2:$I$601,"Pendiente")=0,"—",_xlfn.MINIFS(Cuotas!$E$2:$E$601,Cuotas!$A$2:$A$601,$A6,Cuotas!$I$2:$I$601,"Pendiente"))) | Q6: =IF($A6="","",COUNTIFS(Cuotas!$A$2:$A$601,$A6,Cuotas!$I$2:$I$601,"Pagado")&"/"&COUNTIFS(Cuotas!$A$2:$A$601,$A6)) | R6: =IF($A6="","",IF(COUNTIFS(Cuotas!$A$2:$A$601,$A6,Cuotas!$I$2:$I$601,"Pendiente")=0,"Terminado",IF(P6<TODAY(),"Atrasado","Al día")))
I7: =IF($A7="","",IF(E7="%",D7*F7/100,IF(E7="Fijo por mes",F7*G7,F7))) | J7: =IF($A7="","",ROUNDUP(D7/G7,0)) | K7: =IF($A7="","",ROUNDDOWN(I7/G7,0)) | L7: =IF($A7="","",J7+K7) | M7: =IF($A7="","",IF(E7="%",D7&"*"&F7&"%",IF(E7="Fijo por mes",D7&"cap+"&F7&"int/mes",D7&"cap+"&I7&"int"))&IF(G7>1,IF(E7="Fijo por mes"," x ","/")&G7&"mes","")&" → "&J7&"cap+"&K7&"int="&L7) | N7: =IF($A7="","",SUMIFS(Cuotas!$F$2:$F$601,Cuotas!$A$2:$A$601,$A7,Cuotas!$I$2:$I$601,"Pendiente")) | O7: =IF($A7="","",SUMIFS(Cuotas!$G$2:$G$601,Cuotas!$A$2:$A$601,$A7,Cuotas!$I$2:$I$601,"Pagado")) | P7: =IF($A7="","",IF(COUNTIFS(Cuotas!$A$2:$A$601,$A7,Cuotas!$I$2:$I$601,"Pendiente")=0,"—",_xlfn.MINIFS(Cuotas!$E$2:$E$601,Cuotas!$A$2:$A$601,$A7,Cuotas!$I$2:$I$601,"Pendiente"))) | Q7: =IF($A7="","",COUNTIFS(Cuotas!$A$2:$A$601,$A7,Cuotas!$I$2:$I$601,"Pagado")&"/"&COUNTIFS(Cuotas!$A$2:$A$601,$A7)) | R7: =IF($A7="","",IF(COUNTIFS(Cuotas!$A$2:$A$601,$A7,Cuotas!$I$2:$I$601,"Pendiente")=0,"Terminado",IF(P7<TODAY(),"Atrasado","Al día")))
I8: =IF($A8="","",IF(E8="%",D8*F8/100,IF(E8="Fijo por mes",F8*G8,F8))) | J8: =IF($A8="","",ROUNDUP(D8/G8,0)) | K8: =IF($A8="","",ROUNDDOWN(I8/G8,0)) | L8: =IF($A8="","",J8+K8) | M8: =IF($A8="","",IF(E8="%",D8&"*"&F8&"%",IF(E8="Fijo por mes",D8&"cap+"&F8&"int/mes",D8&"cap+"&I8&"int"))&IF(G8>1,IF(E8="Fijo por mes"," x ","/")&G8&"mes","")&" → "&J8&"cap+"&K8&"int="&L8) | N8: =IF($A8="","",SUMIFS(Cuotas!$F$2:$F$601,Cuotas!$A$2:$A$601,$A8,Cuotas!$I$2:$I$601,"Pendiente")) | O8: =IF($A8="","",SUMIFS(Cuotas!$G$2:$G$601,Cuotas!$A$2:$A$601,$A8,Cuotas!$I$2:$I$601,"Pagado")) | P8: =IF($A8="","",IF(COUNTIFS(Cuotas!$A$2:$A$601,$A8,Cuotas!$I$2:$I$601,"Pendiente")=0,"—",_xlfn.MINIFS(Cuotas!$E$2:$E$601,Cuotas!$A$2:$A$601,$A8,Cuotas!$I$2:$I$601,"Pendiente"))) | Q8: =IF($A8="","",COUNTIFS(Cuotas!$A$2:$A$601,$A8,Cuotas!$I$2:$I$601,"Pagado")&"/"&COUNTIFS(Cuotas!$A$2:$A$601,$A8)) | R8: =IF($A8="","",IF(COUNTIFS(Cuotas!$A$2:$A$601,$A8,Cuotas!$I$2:$I$601,"Pendiente")=0,"Terminado",IF(P8<TODAY(),"Atrasado","Al día")))
I9: =IF($A9="","",IF(E9="%",D9*F9/100,IF(E9="Fijo por mes",F9*G9,F9))) | J9: =IF($A9="","",ROUNDUP(D9/G9,0)) | K9: =IF($A9="","",ROUNDDOWN(I9/G9,0)) | L9: =IF($A9="","",J9+K9) | M9: =IF($A9="","",IF(E9="%",D9&"*"&F9&"%",IF(E9="Fijo por mes",D9&"cap+"&F9&"int/mes",D9&"cap+"&I9&"int"))&IF(G9>1,IF(E9="Fijo por mes"," x ","/")&G9&"mes","")&" → "&J9&"cap+"&K9&"int="&L9) | N9: =IF($A9="","",SUMIFS(Cuotas!$F$2:$F$601,Cuotas!$A$2:$A$601,$A9,Cuotas!$I$2:$I$601,"Pendiente")) | O9: =IF($A9="","",SUMIFS(Cuotas!$G$2:$G$601,Cuotas!$A$2:$A$601,$A9,Cuotas!$I$2:$I$601,"Pagado")) | P9: =IF($A9="","",IF(COUNTIFS(Cuotas!$A$2:$A$601,$A9,Cuotas!$I$2:$I$601,"Pendiente")=0,"—",_xlfn.MINIFS(Cuotas!$E$2:$E$601,Cuotas!$A$2:$A$601,$A9,Cuotas!$I$2:$I$601,"Pendiente"))) | Q9: =IF($A9="","",COUNTIFS(Cuotas!$A$2:$A$601,$A9,Cuotas!$I$2:$I$601,"Pagado")&"/"&COUNTIFS(Cuotas!$A$2:$A$601,$A9)) | R9: =IF($A9="","",IF(COUNTIFS(Cuotas!$A$2:$A$601,$A9,Cuotas!$I$2:$I$601,"Pendiente")=0,"Terminado",IF(P9<TODAY(),"Atrasado","Al día")))
I10: =IF($A10="","",IF(E10="%",D10*F10/100,IF(E10="Fijo por mes",F10*G10,F10))) | J10: =IF($A10="","",ROUNDUP(D10/G10,0)) | K10: =IF($A10="","",ROUNDDOWN(I10/G10,0)) | L10: =IF($A10="","",J10+K10) | M10: =IF($A10="","",IF(E10="%",D10&"*"&F10&"%",IF(E10="Fijo por mes",D10&"cap+"&F10&"int/mes",D10&"cap+"&I10&"int"))&IF(G10>1,IF(E10="Fijo por mes"," x ","/")&G10&"mes","")&" → "&J10&"cap+"&K10&"int="&L10) | N10: =IF($A10="","",SUMIFS(Cuotas!$F$2:$F$601,Cuotas!$A$2:$A$601,$A10,Cuotas!$I$2:$I$601,"Pendiente")) | O10: =IF($A10="","",SUMIFS(Cuotas!$G$2:$G$601,Cuotas!$A$2:$A$601,$A10,Cuotas!$I$2:$I$601,"Pagado")) | P10: =IF($A10="","",IF(COUNTIFS(Cuotas!$A$2:$A$601,$A10,Cuotas!$I$2:$I$601,"Pendiente")=0,"—",_xlfn.MINIFS(Cuotas!$E$2:$E$601,Cuotas!$A$2:$A$601,$A10,Cuotas!$I$2:$I$601,"Pendiente"))) | Q10: =IF($A10="","",COUNTIFS(Cuotas!$A$2:$A$601,$A10,Cuotas!$I$2:$I$601,"Pagado")&"/"&COUNTIFS(Cuotas!$A$2:$A$601,$A10)) | R10: =IF($A10="","",IF(COUNTIFS(Cuotas!$A$2:$A$601,$A10,Cuotas!$I$2:$I$601,"Pendiente")=0,"Terminado",IF(P10<TODAY(),"Atrasado","Al día")))
I11: =IF($A11="","",IF(E11="%",D11*F11/100,IF(E11="Fijo por mes",F11*G11,F11))) | J11: =IF($A11="","",ROUNDUP(D11/G11,0)) | K11: =IF($A11="","",ROUNDDOWN(I11/G11,0)) | L11: =IF($A11="","",J11+K11) | M11: =IF($A11="","",IF(E11="%",D11&"*"&F11&"%",IF(E11="Fijo por mes",D11&"cap+"&F11&"int/mes",D11&"cap+"&I11&"int"))&IF(G11>1,IF(E11="Fijo por mes"," x ","/")&G11&"mes","")&" → "&J11&"cap+"&K11&"int="&L11) | N11: =IF($A11="","",SUMIFS(Cuotas!$F$2:$F$601,Cuotas!$A$2:$A$601,$A11,Cuotas!$I$2:$I$601,"Pendiente")) | O11: =IF($A11="","",SUMIFS(Cuotas!$G$2:$G$601,Cuotas!$A$2:$A$601,$A11,Cuotas!$I$2:$I$601,"Pagado")) | P11: =IF($A11="","",IF(COUNTIFS(Cuotas!$A$2:$A$601,$A11,Cuotas!$I$2:$I$601,"Pendiente")=0,"—",_xlfn.MINIFS(Cuotas!$E$2:$E$601,Cuotas!$A$2:$A$601,$A11,Cuotas!$I$2:$I$601,"Pendiente"))) | Q11: =IF($A11="","",COUNTIFS(Cuotas!$A$2:$A$601,$A11,Cuotas!$I$2:$I$601,"Pagado")&"/"&COUNTIFS(Cuotas!$A$2:$A$601,$A11)) | R11: =IF($A11="","",IF(COUNTIFS(Cuotas!$A$2:$A$601,$A11,Cuotas!$I$2:$I$601,"Pendiente")=0,"Terminado",IF(P11<TODAY(),"Atrasado","Al día")))
I12: =IF($A12="","",IF(E12="%",D12*F12/100,IF(E12="Fijo por mes",F12*G12,F12))) | J12: =IF($A12="","",ROUNDUP(D12/G12,0)) | K12: =IF($A12="","",ROUNDDOWN(I12/G12,0)) | L12: =IF($A12="","",J12+K12) | M12: =IF($A12="","",IF(E12="%",D12&"*"&F12&"%",IF(E12="Fijo por mes",D12&"cap+"&F12&"int/mes",D12&"cap+"&I12&"int"))&IF(G12>1,IF(E12="Fijo por mes"," x ","/")&G12&"mes","")&" → "&J12&"cap+"&K12&"int="&L12) | N12: =IF($A12="","",SUMIFS(Cuotas!$F$2:$F$601,Cuotas!$A$2:$A$601,$A12,Cuotas!$I$2:$I$601,"Pendiente")) | O12: =IF($A12="","",SUMIFS(Cuotas!$G$2:$G$601,Cuotas!$A$2:$A$601,$A12,Cuotas!$I$2:$I$601,"Pagado")) | P12: =IF($A12="","",IF(COUNTIFS(Cuotas!$A$2:$A$601,$A12,Cuotas!$I$2:$I$601,"Pendiente")=0,"—",_xlfn.MINIFS(Cuotas!$E$2:$E$601,Cuotas!$A$2:$A$601,$A12,Cuotas!$I$2:$I$601,"Pendiente"))) | Q12: =IF($A12="","",COUNTIFS(Cuotas!$A$2:$A$601,$A12,Cuotas!$I$2:$I$601,"Pagado")&"/"&COUNTIFS(Cuotas!$A$2:$A$601,$A12)) | R12: =IF($A12="","",IF(COUNTIFS(Cuotas!$A$2:$A$601,$A12,Cuotas!$I$2:$I$601,"Pendiente")=0,"Terminado",IF(P12<TODAY(),"Atrasado","Al día")))
I13: =IF($A13="","",IF(E13="%",D13*F13/100,IF(E13="Fijo por mes",F13*G13,F13))) | J13: =IF($A13="","",ROUNDUP(D13/G13,0)) | K13: =IF($A13="","",ROUNDDOWN(I13/G13,0)) | L13: =IF($A13="","",J13+K13) | M13: =IF($A13="","",IF(E13="%",D13&"*"&F13&"%",IF(E13="Fijo por mes",D13&"cap+"&F13&"int/mes",D13&"cap+"&I13&"int"))&IF(G13>1,IF(E13="Fijo por mes"," x ","/")&G13&"mes","")&" → "&J13&"cap+"&K13&"int="&L13) | N13: =IF($A13="","",SUMIFS(Cuotas!$F$2:$F$601,Cuotas!$A$2:$A$601,$A13,Cuotas!$I$2:$I$601,"Pendiente")) | O13: =IF($A13="","",SUMIFS(Cuotas!$G$2:$G$601,Cuotas!$A$2:$A$601,$A13,Cuotas!$I$2:$I$601,"Pagado")) | P13: =IF($A13="","",IF(COUNTIFS(Cuotas!$A$2:$A$601,$A13,Cuotas!$I$2:$I$601,"Pendiente")=0,"—",_xlfn.MINIFS(Cuotas!$E$2:$E$601,Cuotas!$A$2:$A$601,$A13,Cuotas!$I$2:$I$601,"Pendiente"))) | Q13: =IF($A13="","",COUNTIFS(Cuotas!$A$2:$A$601,$A13,Cuotas!$I$2:$I$601,"Pagado")&"/"&COUNTIFS(Cuotas!$A$2:$A$601,$A13)) | R13: =IF($A13="","",IF(COUNTIFS(Cuotas!$A$2:$A$601,$A13,Cuotas!$I$2:$I$601,"Pendiente")=0,"Terminado",IF(P13<TODAY(),"Atrasado","Al día")))
I14: =IF($A14="","",IF(E14="%",D14*F14/100,IF(E14="Fijo por mes",F14*G14,F14))) | J14: =IF($A14="","",ROUNDUP(D14/G14,0)) | K14: =IF($A14="","",ROUNDDOWN(I14/G14,0)) | L14: =IF($A14="","",J14+K14) | M14: =IF($A14="","",IF(E14="%",D14&"*"&F14&"%",IF(E14="Fijo por mes",D14&"cap+"&F14&"int/mes",D14&"cap+"&I14&"int"))&IF(G14>1,IF(E14="Fijo por mes"," x ","/")&G14&"mes","")&" → "&J14&"cap+"&K14&"int="&L14) | N14: =IF($A14="","",SUMIFS(Cuotas!$F$2:$F$601,Cuotas!$A$2:$A$601,$A14,Cuotas!$I$2:$I$601,"Pendiente")) | O14: =IF($A14="","",SUMIFS(Cuotas!$G$2:$G$601,Cuotas!$A$2:$A$601,$A14,Cuotas!$I$2:$I$601,"Pagado")) | P14: =IF($A14="","",IF(COUNTIFS(Cuotas!$A$2:$A$601,$A14,Cuotas!$I$2:$I$601,"Pendiente")=0,"—",_xlfn.MINIFS(Cuotas!$E$2:$E$601,Cuotas!$A$2:$A$601,$A14,Cuotas!$I$2:$I$601,"Pendiente"))) | Q14: =IF($A14="","",COUNTIFS(Cuotas!$A$2:$A$601,$A14,Cuotas!$I$2:$I$601,"Pagado")&"/"&COUNTIFS(Cuotas!$A$2:$A$601,$A14)) | R14: =IF($A14="","",IF(COUNTIFS(Cuotas!$A$2:$A$601,$A14,Cuotas!$I$2:$I$601,"Pendiente")=0,"Terminado",IF(P14<TODAY(),"Atrasado","Al día")))
I15: =IF($A15="","",IF(E15="%",D15*F15/100,IF(E15="Fijo por mes",F15*G15,F15))) | J15: =IF($A15="","",ROUNDUP(D15/G15,0)) | K15: =IF($A15="","",ROUNDDOWN(I15/G15,0)) | L15: =IF($A15="","",J15+K15) | M15: =IF($A15="","",IF(E15="%",D15&"*"&F15&"%",IF(E15="Fijo por mes",D15&"cap+"&F15&"int/mes",D15&"cap+"&I15&"int"))&IF(G15>1,IF(E15="Fijo por mes"," x ","/")&G15&"mes","")&" → "&J15&"cap+"&K15&"int="&L15) | N15: =IF($A15="","",SUMIFS(Cuotas!$F$2:$F$601,Cuotas!$A$2:$A$601,$A15,Cuotas!$I$2:$I$601,"Pendiente")) | O15: =IF($A15="","",SUMIFS(Cuotas!$G$2:$G$601,Cuotas!$A$2:$A$601,$A15,Cuotas!$I$2:$I$601,"Pagado")) | P15: =IF($A15="","",IF(COUNTIFS(Cuotas!$A$2:$A$601,$A15,Cuotas!$I$2:$I$601,"Pendiente")=0,"—",_xlfn.MINIFS(Cuotas!$E$2:$E$601,Cuotas!$A$2:$A$601,$A15,Cuotas!$I$2:$I$601,"Pendiente"))) | Q15: =IF($A15="","",COUNTIFS(Cuotas!$A$2:$A$601,$A15,Cuotas!$I$2:$I$601,"Pagado")&"/"&COUNTIFS(Cuotas!$A$2:$A$601,$A15)) | R15: =IF($A15="","",IF(COUNTIFS(Cuotas!$A$2:$A$601,$A15,Cuotas!$I$2:$I$601,"Pendiente")=0,"Terminado",IF(P15<TODAY(),"Atrasado","Al día")))
I16: =IF($A16="","",IF(E16="%",D16*F16/100,IF(E16="Fijo por mes",F16*G16,F16))) | J16: =IF($A16="","",ROUNDUP(D16/G16,0)) | K16: =IF($A16="","",ROUNDDOWN(I16/G16,0)) | L16: =IF($A16="","",J16+K16) | M16: =IF($A16="","",IF(E16="%",D16&"*"&F16&"%",IF(E16="Fijo por mes",D16&"cap+"&F16&"int/mes",D16&"cap+"&I16&"int"))&IF(G16>1,IF(E16="Fijo por mes"," x ","/")&G16&"mes","")&" → "&J16&"cap+"&K16&"int="&L16) | N16: =IF($A16="","",SUMIFS(Cuotas!$F$2:$F$601,Cuotas!$A$2:$A$601,$A16,Cuotas!$I$2:$I$601,"Pendiente")) | O16: =IF($A16="","",SUMIFS(Cuotas!$G$2:$G$601,Cuotas!$A$2:$A$601,$A16,Cuotas!$I$2:$I$601,"Pagado")) | P16: =IF($A16="","",IF(COUNTIFS(Cuotas!$A$2:$A$601,$A16,Cuotas!$I$2:$I$601,"Pendiente")=0,"—",_xlfn.MINIFS(Cuotas!$E$2:$E$601,Cuotas!$A$2:$A$601,$A16,Cuotas!$I$2:$I$601,"Pendiente"))) | Q16: =IF($A16="","",COUNTIFS(Cuotas!$A$2:$A$601,$A16,Cuotas!$I$2:$I$601,"Pagado")&"/"&COUNTIFS(Cuotas!$A$2:$A$601,$A16)) | R16: =IF($A16="","",IF(COUNTIFS(Cuotas!$A$2:$A$601,$A16,Cuotas!$I$2:$I$601,"Pendiente")=0,"Terminado",IF(P16<TODAY(),"Atrasado","Al día")))
... I101: =IF($A101="","",IF(E101="%",D101*F101/100,IF(E101="Fijo por mes",F101*G101,F101))) | J101: =IF($A101="","",ROUNDUP(D101/G101,0)) | K101: =IF($A101="","",ROUNDDOWN(I101/G101,0)) | L101: =IF($A101="","",J101+K101) | M101: =IF($A101="","",IF(E101="%",D101&"*"&F101&"%",IF(E101="Fijo por mes",D101&"cap+"&F101&"int/mes",D101&"cap+"&I101&"int"))&IF(G101>1,IF(E101="Fijo por mes"," x ","/")&G101&"mes","")&" → "&J101&"cap+"&K101&"int="&L101) | N101: =IF($A101="","",SUMIFS(Cuotas!$F$2:$F$601,Cuotas!$A$2:$A$601,$A101,Cuotas!$I$2:$I$601,"Pendiente")) | O101: =IF($A101="","",SUMIFS(Cuotas!$G$2:$G$601,Cuotas!$A$2:$A$601,$A101,Cuotas!$I$2:$I$601,"Pagado")) | P101: =IF($A101="","",IF(COUNTIFS(Cuotas!$A$2:$A$601,$A101,Cuotas!$I$2:$I$601,"Pendiente")=0,"—",_xlfn.MINIFS(Cuotas!$E$2:$E$601,Cuotas!$A$2:$A$601,$A101,Cuotas!$I$2:$I$601,"Pendiente"))) | Q101: =IF($A101="","",COUNTIFS(Cuotas!$A$2:$A$601,$A101,Cuotas!$I$2:$I$601,"Pagado")&"/"&COUNTIFS(Cuotas!$A$2:$A$601,$A101)) | R101: =IF($A101="","",IF(COUNTIFS(Cuotas!$A$2:$A$601,$A101,Cuotas!$I$2:$I$601,"Pendiente")=0,"Terminado",IF(P101<TODAY(),"Atrasado","Al día")))

Sheet Cuotas
A1: Préstamo N° | B1: Cliente | C1: Cuota N° | D1: Tipo | E1: Fecha límite | F1: Capital | G1: Interés | H1: Total | I1: Estado | J1: Fecha de pago | K1: Días de atraso | L1: Situación | M1: Recordatorio
A2: 2 | B2: =IF($A2="","",INDEX('Préstamos'!$B$2:$B$101,MATCH($A2,'Préstamos'!$A$2:$A$101,0))) | C2: 1 | D2: Normal | E2: 46264 | F2: =IF($A2="","",IF(D2="Solo interés",0,IF(AND(D2<>"Solo interés",C2=INDEX('Préstamos'!$G$2:$G$101,MATCH($A2,'Préstamos'!$A$2:$A$101,0))),INDEX('Préstamos'!$D$2:$D$101,MATCH($A2,'Préstamos'!$A$2:$A$101,0))-INDEX('Préstamos'!$J$2:$J$101,MATCH($A2,'Préstamos'!$A$2:$A$101,0))*(INDEX('Préstamos'!$G$2:$G$101,MATCH($A2,'Préstamos'!$A$2:$A$101,0))-1),INDEX('Préstamos'!$J$2:$J$101,MATCH($A2,'Préstamos'!$A$2:$A$101,0))))) | G2: =IF($A2="","",IF(AND(D2<>"Solo interés",C2=INDEX('Préstamos'!$G$2:$G$101,MATCH($A2,'Préstamos'!$A$2:$A$101,0))),INDEX('Préstamos'!$I$2:$I$101,MATCH($A2,'Préstamos'!$A$2:$A$101,0))-INDEX('Préstamos'!$K$2:$K$101,MATCH($A2,'Préstamos'!$A$2:$A$101,0))*(INDEX('Préstamos'!$G$2:$G$101,MATCH($A2,'Préstamos'!$A$2:$A$101,0))-1),INDEX('Préstamos'!$K$2:$K$101,MATCH($A2,'Préstamos'!$A$2:$A$101,0)))) | H2: =IF($A2="","",F2+G2) | I2: Pagado | J2: 46264 | K2: =IF(OR($A2="",I2="Pagado"),"",MAX(0,TODAY()-E2)) | L2: =IF($A2="","",IF(I2="Pagado","Pagado",IF(E2<TODAY(),"Atrasado",IF(E2<=EOMONTH(TODAY(),0),"Este mes","Pendiente")))) | M2: =IF(OR($A2="",I2="Pagado"),"",HYPERLINK("https://wa.me/"&IF(INDEX('Préstamos'!$C$2:$C$101,MATCH($A2,'Préstamos'!$A$2:$A$101,0))="","","51"&SUBSTITUTE(INDEX('Préstamos'!$C$2:$C$101,MATCH($A2,'Préstamos'!$A$2:$A$101,0))," ",""))&"?text="&SUBSTITUTE("Hola "&B2&", te recuerdo que tu cuota de S/ "&H2&IF(E2<TODAY()," vencio el "," vence el ")&TEXT(E2,"dd/mm")&". Gracias!"," ","%20"),"WhatsApp"))
A3: 2 | B3: =IF($A3="","",INDEX('Préstamos'!$B$2:$B$101,MATCH($A3,'Préstamos'!$A$2:$A$101,0))) | D3: Solo interés | E3: 46295 | F3: =IF($A3="","",IF(D3="Solo interés",0,IF(AND(D3<>"Solo interés",C3=INDEX('Préstamos'!$G$2:$G$101,MATCH($A3,'Préstamos'!$A$2:$A$101,0))),INDEX('Préstamos'!$D$2:$D$101,MATCH($A3,'Préstamos'!$A$2:$A$101,0))-INDEX('Préstamos'!$J$2:$J$101,MATCH($A3,'Préstamos'!$A$2:$A$101,0))*(INDEX('Préstamos'!$G$2:$G$101,MATCH($A3,'Préstamos'!$A$2:$A$101,0))-1),INDEX('Préstamos'!$J$2:$J$101,MATCH($A3,'Préstamos'!$A$2:$A$101,0))))) | G3: =IF($A3="","",IF(AND(D3<>"Solo interés",C3=INDEX('Préstamos'!$G$2:$G$101,MATCH($A3,'Préstamos'!$A$2:$A$101,0))),INDEX('Préstamos'!$I$2:$I$101,MATCH($A3,'Préstamos'!$A$2:$A$101,0))-INDEX('Préstamos'!$K$2:$K$101,MATCH($A3,'Préstamos'!$A$2:$A$101,0))*(INDEX('Préstamos'!$G$2:$G$101,MATCH($A3,'Préstamos'!$A$2:$A$101,0))-1),INDEX('Préstamos'!$K$2:$K$101,MATCH($A3,'Préstamos'!$A$2:$A$101,0)))) | H3: =IF($A3="","",F3+G3) | I3: Pagado | J3: 46295 | K3: =IF(OR($A3="",I3="Pagado"),"",MAX(0,TODAY()-E3)) | L3: =IF($A3="","",IF(I3="Pagado","Pagado",IF(E3<TODAY(),"Atrasado",IF(E3<=EOMONTH(TODAY(),0),"Este mes","Pendiente")))) | M3: =IF(OR($A3="",I3="Pagado"),"",HYPERLINK("https://wa.me/"&IF(INDEX('Préstamos'!$C$2:$C$101,MATCH($A3,'Préstamos'!$A$2:$A$101,0))="","","51"&SUBSTITUTE(INDEX('Préstamos'!$C$2:$C$101,MATCH($A3,'Préstamos'!$A$2:$A$101,0))," ",""))&"?text="&SUBSTITUTE("Hola "&B3&", te recuerdo que tu cuota de S/ "&H3&IF(E3<TODAY()," vencio el "," vence el ")&TEXT(E3,"dd/mm")&". Gracias!"," ","%20"),"WhatsApp"))
A4: 3 | B4: =IF($A4="","",INDEX('Préstamos'!$B$2:$B$101,MATCH($A4,'Préstamos'!$A$2:$A$101,0))) | C4: 1 | D4: Normal | E4: 46295 | F4: =IF($A4="","",IF(D4="Solo interés",0,IF(AND(D4<>"Solo interés",C4=INDEX('Préstamos'!$G$2:$G$101,MATCH($A4,'Préstamos'!$A$2:$A$101,0))),INDEX('Préstamos'!$D$2:$D$101,MATCH($A4,'Préstamos'!$A$2:$A$101,0))-INDEX('Préstamos'!$J$2:$J$101,MATCH($A4,'Préstamos'!$A$2:$A$101,0))*(INDEX('Préstamos'!$G$2:$G$101,MATCH($A4,'Préstamos'!$A$2:$A$101,0))-1),INDEX('Préstamos'!$J$2:$J$101,MATCH($A4,'Préstamos'!$A$2:$A$101,0))))) | G4: =IF($A4="","",IF(AND(D4<>"Solo interés",C4=INDEX('Préstamos'!$G$2:$G$101,MATCH($A4,'Préstamos'!$A$2:$A$101,0))),INDEX('Préstamos'!$I$2:$I$101,MATCH($A4,'Préstamos'!$A$2:$A$101,0))-INDEX('Préstamos'!$K$2:$K$101,MATCH($A4,'Préstamos'!$A$2:$A$101,0))*(INDEX('Préstamos'!$G$2:$G$101,MATCH($A4,'Préstamos'!$A$2:$A$101,0))-1),INDEX('Préstamos'!$K$2:$K$101,MATCH($A4,'Préstamos'!$A$2:$A$101,0)))) | H4: =IF($A4="","",F4+G4) | I4: Pagado | J4: 46295 | K4: =IF(OR($A4="",I4="Pagado"),"",MAX(0,TODAY()-E4)) | L4: =IF($A4="","",IF(I4="Pagado","Pagado",IF(E4<TODAY(),"Atrasado",IF(E4<=EOMONTH(TODAY(),0),"Este mes","Pendiente")))) | M4: =IF(OR($A4="",I4="Pagado"),"",HYPERLINK("https://wa.me/"&IF(INDEX('Préstamos'!$C$2:$C$101,MATCH($A4,'Préstamos'!$A$2:$A$101,0))="","","51"&SUBSTITUTE(INDEX('Préstamos'!$C$2:$C$101,MATCH($A4,'Préstamos'!$A$2:$A$101,0))," ",""))&"?text="&SUBSTITUTE("Hola "&B4&", te recuerdo que tu cuota de S/ "&H4&IF(E4<TODAY()," vencio el "," vence el ")&TEXT(E4,"dd/mm")&". Gracias!"," ","%20"),"WhatsApp"))
A5: 1 | B5: =IF($A5="","",INDEX('Préstamos'!$B$2:$B$101,MATCH($A5,'Préstamos'!$A$2:$A$101,0))) | C5: 1 | D5: Normal | E5: 46311 | F5: =IF($A5="","",IF(D5="Solo interés",0,IF(AND(D5<>"Solo interés",C5=INDEX('Préstamos'!$G$2:$G$101,MATCH($A5,'Préstamos'!$A$2:$A$101,0))),INDEX('Préstamos'!$D$2:$D$101,MATCH($A5,'Préstamos'!$A$2:$A$101,0))-INDEX('Préstamos'!$J$2:$J$101,MATCH($A5,'Préstamos'!$A$2:$A$101,0))*(INDEX('Préstamos'!$G$2:$G$101,MATCH($A5,'Préstamos'!$A$2:$A$101,0))-1),INDEX('Préstamos'!$J$2:$J$101,MATCH($A5,'Préstamos'!$A$2:$A$101,0))))) | G5: =IF($A5="","",IF(AND(D5<>"Solo interés",C5=INDEX('Préstamos'!$G$2:$G$101,MATCH($A5,'Préstamos'!$A$2:$A$101,0))),INDEX('Préstamos'!$I$2:$I$101,MATCH($A5,'Préstamos'!$A$2:$A$101,0))-INDEX('Préstamos'!$K$2:$K$101,MATCH($A5,'Préstamos'!$A$2:$A$101,0))*(INDEX('Préstamos'!$G$2:$G$101,MATCH($A5,'Préstamos'!$A$2:$A$101,0))-1),INDEX('Préstamos'!$K$2:$K$101,MATCH($A5,'Préstamos'!$A$2:$A$101,0)))) | H5: =IF($A5="","",F5+G5) | I5: Pendiente | K5: =IF(OR($A5="",I5="Pagado"),"",MAX(0,TODAY()-E5)) | L5: =IF($A5="","",IF(I5="Pagado","Pagado",IF(E5<TODAY(),"Atrasado",IF(E5<=EOMONTH(TODAY(),0),"Este mes","Pendiente")))) | M5: =IF(OR($A5="",I5="Pagado"),"",HYPERLINK("https://wa.me/"&IF(INDEX('Préstamos'!$C$2:$C$101,MATCH($A5,'Préstamos'!$A$2:$A$101,0))="","","51"&SUBSTITUTE(INDEX('Préstamos'!$C$2:$C$101,MATCH($A5,'Préstamos'!$A$2:$A$101,0))," ",""))&"?text="&SUBSTITUTE("Hola "&B5&", te recuerdo que tu cuota de S/ "&H5&IF(E5<TODAY()," vencio el "," vence el ")&TEXT(E5,"dd/mm")&". Gracias!"," ","%20"),"WhatsApp"))
A6: 2 | B6: =IF($A6="","",INDEX('Préstamos'!$B$2:$B$101,MATCH($A6,'Préstamos'!$A$2:$A$101,0))) | C6: 2 | D6: Normal | E6: 46325 | F6: =IF($A6="","",IF(D6="Solo interés",0,IF(AND(D6<>"Solo interés",C6=INDEX('Préstamos'!$G$2:$G$101,MATCH($A6,'Préstamos'!$A$2:$A$101,0))),INDEX('Préstamos'!$D$2:$D$101,MATCH($A6,'Préstamos'!$A$2:$A$101,0))-INDEX('Préstamos'!$J$2:$J$101,MATCH($A6,'Préstamos'!$A$2:$A$101,0))*(INDEX('Préstamos'!$G$2:$G$101,MATCH($A6,'Préstamos'!$A$2:$A$101,0))-1),INDEX('Préstamos'!$J$2:$J$101,MATCH($A6,'Préstamos'!$A$2:$A$101,0))))) | G6: =IF($A6="","",IF(AND(D6<>"Solo interés",C6=INDEX('Préstamos'!$G$2:$G$101,MATCH($A6,'Préstamos'!$A$2:$A$101,0))),INDEX('Préstamos'!$I$2:$I$101,MATCH($A6,'Préstamos'!$A$2:$A$101,0))-INDEX('Préstamos'!$K$2:$K$101,MATCH($A6,'Préstamos'!$A$2:$A$101,0))*(INDEX('Préstamos'!$G$2:$G$101,MATCH($A6,'Préstamos'!$A$2:$A$101,0))-1),INDEX('Préstamos'!$K$2:$K$101,MATCH($A6,'Préstamos'!$A$2:$A$101,0)))) | H6: =IF($A6="","",F6+G6) | I6: Pendiente | K6: =IF(OR($A6="",I6="Pagado"),"",MAX(0,TODAY()-E6)) | L6: =IF($A6="","",IF(I6="Pagado","Pagado",IF(E6<TODAY(),"Atrasado",IF(E6<=EOMONTH(TODAY(),0),"Este mes","Pendiente")))) | M6: =IF(OR($A6="",I6="Pagado"),"",HYPERLINK("https://wa.me/"&IF(INDEX('Préstamos'!$C$2:$C$101,MATCH($A6,'Préstamos'!$A$2:$A$101,0))="","","51"&SUBSTITUTE(INDEX('Préstamos'!$C$2:$C$101,MATCH($A6,'Préstamos'!$A$2:$A$101,0))," ",""))&"?text="&SUBSTITUTE("Hola "&B6&", te recuerdo que tu cuota de S/ "&H6&IF(E6<TODAY()," vencio el "," vence el ")&TEXT(E6,"dd/mm")&". Gracias!"," ","%20"),"WhatsApp"))
A7: 3 | B7: =IF($A7="","",INDEX('Préstamos'!$B$2:$B$101,MATCH($A7,'Préstamos'!$A$2:$A$101,0))) | C7: 2 | D7: Normal | E7: 46325 | F7: =IF($A7="","",IF(D7="Solo interés",0,IF(AND(D7<>"Solo interés",C7=INDEX('Préstamos'!$G$2:$G$101,MATCH($A7,'Préstamos'!$A$2:$A$101,0))),INDEX('Préstamos'!$D$2:$D$101,MATCH($A7,'Préstamos'!$A$2:$A$101,0))-INDEX('Préstamos'!$J$2:$J$101,MATCH($A7,'Préstamos'!$A$2:$A$101,0))*(INDEX('Préstamos'!$G$2:$G$101,MATCH($A7,'Préstamos'!$A$2:$A$101,0))-1),INDEX('Préstamos'!$J$2:$J$101,MATCH($A7,'Préstamos'!$A$2:$A$101,0))))) | G7: =IF($A7="","",IF(AND(D7<>"Solo interés",C7=INDEX('Préstamos'!$G$2:$G$101,MATCH($A7,'Préstamos'!$A$2:$A$101,0))),INDEX('Préstamos'!$I$2:$I$101,MATCH($A7,'Préstamos'!$A$2:$A$101,0))-INDEX('Préstamos'!$K$2:$K$101,MATCH($A7,'Préstamos'!$A$2:$A$101,0))*(INDEX('Préstamos'!$G$2:$G$101,MATCH($A7,'Préstamos'!$A$2:$A$101,0))-1),INDEX('Préstamos'!$K$2:$K$101,MATCH($A7,'Préstamos'!$A$2:$A$101,0)))) | H7: =IF($A7="","",F7+G7) | I7: Pendiente | K7: =IF(OR($A7="",I7="Pagado"),"",MAX(0,TODAY()-E7)) | L7: =IF($A7="","",IF(I7="Pagado","Pagado",IF(E7<TODAY(),"Atrasado",IF(E7<=EOMONTH(TODAY(),0),"Este mes","Pendiente")))) | M7: =IF(OR($A7="",I7="Pagado"),"",HYPERLINK("https://wa.me/"&IF(INDEX('Préstamos'!$C$2:$C$101,MATCH($A7,'Préstamos'!$A$2:$A$101,0))="","","51"&SUBSTITUTE(INDEX('Préstamos'!$C$2:$C$101,MATCH($A7,'Préstamos'!$A$2:$A$101,0))," ",""))&"?text="&SUBSTITUTE("Hola "&B7&", te recuerdo que tu cuota de S/ "&H7&IF(E7<TODAY()," vencio el "," vence el ")&TEXT(E7,"dd/mm")&". Gracias!"," ","%20"),"WhatsApp"))
A8: 1 | B8: =IF($A8="","",INDEX('Préstamos'!$B$2:$B$101,MATCH($A8,'Préstamos'!$A$2:$A$101,0))) | C8: 2 | D8: Normal | E8: 46342 | F8: =IF($A8="","",IF(D8="Solo interés",0,IF(AND(D8<>"Solo interés",C8=INDEX('Préstamos'!$G$2:$G$101,MATCH($A8,'Préstamos'!$A$2:$A$101,0))),INDEX('Préstamos'!$D$2:$D$101,MATCH($A8,'Préstamos'!$A$2:$A$101,0))-INDEX('Préstamos'!$J$2:$J$101,MATCH($A8,'Préstamos'!$A$2:$A$101,0))*(INDEX('Préstamos'!$G$2:$G$101,MATCH($A8,'Préstamos'!$A$2:$A$101,0))-1),INDEX('Préstamos'!$J$2:$J$101,MATCH($A8,'Préstamos'!$A$2:$A$101,0))))) | G8: =IF($A8="","",IF(AND(D8<>"Solo interés",C8=INDEX('Préstamos'!$G$2:$G$101,MATCH($A8,'Préstamos'!$A$2:$A$101,0))),INDEX('Préstamos'!$I$2:$I$101,MATCH($A8,'Préstamos'!$A$2:$A$101,0))-INDEX('Préstamos'!$K$2:$K$101,MATCH($A8,'Préstamos'!$A$2:$A$101,0))*(INDEX('Préstamos'!$G$2:$G$101,MATCH($A8,'Préstamos'!$A$2:$A$101,0))-1),INDEX('Préstamos'!$K$2:$K$101,MATCH($A8,'Préstamos'!$A$2:$A$101,0)))) | H8: =IF($A8="","",F8+G8) | I8: Pendiente | K8: =IF(OR($A8="",I8="Pagado"),"",MAX(0,TODAY()-E8)) | L8: =IF($A8="","",IF(I8="Pagado","Pagado",IF(E8<TODAY(),"Atrasado",IF(E8<=EOMONTH(TODAY(),0),"Este mes","Pendiente")))) | M8: =IF(OR($A8="",I8="Pagado"),"",HYPERLINK("https://wa.me/"&IF(INDEX('Préstamos'!$C$2:$C$101,MATCH($A8,'Préstamos'!$A$2:$A$101,0))="","","51"&SUBSTITUTE(INDEX('Préstamos'!$C$2:$C$101,MATCH($A8,'Préstamos'!$A$2:$A$101,0))," ",""))&"?text="&SUBSTITUTE("Hola "&B8&", te recuerdo que tu cuota de S/ "&H8&IF(E8<TODAY()," vencio el "," vence el ")&TEXT(E8,"dd/mm")&". Gracias!"," ","%20"),"WhatsApp"))
A9: 2 | B9: =IF($A9="","",INDEX('Préstamos'!$B$2:$B$101,MATCH($A9,'Préstamos'!$A$2:$A$101,0))) | C9: 3 | D9: Normal | E9: 46356 | F9: =IF($A9="","",IF(D9="Solo interés",0,IF(AND(D9<>"Solo interés",C9=INDEX('Préstamos'!$G$2:$G$101,MATCH($A9,'Préstamos'!$A$2:$A$101,0))),INDEX('Préstamos'!$D$2:$D$101,MATCH($A9,'Préstamos'!$A$2:$A$101,0))-INDEX('Préstamos'!$J$2:$J$101,MATCH($A9,'Préstamos'!$A$2:$A$101,0))*(INDEX('Préstamos'!$G$2:$G$101,MATCH($A9,'Préstamos'!$A$2:$A$101,0))-1),INDEX('Préstamos'!$J$2:$J$101,MATCH($A9,'Préstamos'!$A$2:$A$101,0))))) | G9: =IF($A9="","",IF(AND(D9<>"Solo interés",C9=INDEX('Préstamos'!$G$2:$G$101,MATCH($A9,'Préstamos'!$A$2:$A$101,0))),INDEX('Préstamos'!$I$2:$I$101,MATCH($A9,'Préstamos'!$A$2:$A$101,0))-INDEX('Préstamos'!$K$2:$K$101,MATCH($A9,'Préstamos'!$A$2:$A$101,0))*(INDEX('Préstamos'!$G$2:$G$101,MATCH($A9,'Préstamos'!$A$2:$A$101,0))-1),INDEX('Préstamos'!$K$2:$K$101,MATCH($A9,'Préstamos'!$A$2:$A$101,0)))) | H9: =IF($A9="","",F9+G9) | I9: Pendiente | K9: =IF(OR($A9="",I9="Pagado"),"",MAX(0,TODAY()-E9)) | L9: =IF($A9="","",IF(I9="Pagado","Pagado",IF(E9<TODAY(),"Atrasado",IF(E9<=EOMONTH(TODAY(),0),"Este mes","Pendiente")))) | M9: =IF(OR($A9="",I9="Pagado"),"",HYPERLINK("https://wa.me/"&IF(INDEX('Préstamos'!$C$2:$C$101,MATCH($A9,'Préstamos'!$A$2:$A$101,0))="","","51"&SUBSTITUTE(INDEX('Préstamos'!$C$2:$C$101,MATCH($A9,'Préstamos'!$A$2:$A$101,0))," ",""))&"?text="&SUBSTITUTE("Hola "&B9&", te recuerdo que tu cuota de S/ "&H9&IF(E9<TODAY()," vencio el "," vence el ")&TEXT(E9,"dd/mm")&". Gracias!"," ","%20"),"WhatsApp"))
A10: 3 | B10: =IF($A10="","",INDEX('Préstamos'!$B$2:$B$101,MATCH($A10,'Préstamos'!$A$2:$A$101,0))) | C10: 3 | D10: Normal | E10: 46356 | F10: =IF($A10="","",IF(D10="Solo interés",0,IF(AND(D10<>"Solo interés",C10=INDEX('Préstamos'!$G$2:$G$101,MATCH($A10,'Préstamos'!$A$2:$A$101,0))),INDEX('Préstamos'!$D$2:$D$101,MATCH($A10,'Préstamos'!$A$2:$A$101,0))-INDEX('Préstamos'!$J$2:$J$101,MATCH($A10,'Préstamos'!$A$2:$A$101,0))*(INDEX('Préstamos'!$G$2:$G$101,MATCH($A10,'Préstamos'!$A$2:$A$101,0))-1),INDEX('Préstamos'!$J$2:$J$101,MATCH($A10,'Préstamos'!$A$2:$A$101,0))))) | G10: =IF($A10="","",IF(AND(D10<>"Solo interés",C10=INDEX('Préstamos'!$G$2:$G$101,MATCH($A10,'Préstamos'!$A$2:$A$101,0))),INDEX('Préstamos'!$I$2:$I$101,MATCH($A10,'Préstamos'!$A$2:$A$101,0))-INDEX('Préstamos'!$K$2:$K$101,MATCH($A10,'Préstamos'!$A$2:$A$101,0))*(INDEX('Préstamos'!$G$2:$G$101,MATCH($A10,'Préstamos'!$A$2:$A$101,0))-1),INDEX('Préstamos'!$K$2:$K$101,MATCH($A10,'Préstamos'!$A$2:$A$101,0)))) | H10: =IF($A10="","",F10+G10) | I10: Pendiente | K10: =IF(OR($A10="",I10="Pagado"),"",MAX(0,TODAY()-E10)) | L10: =IF($A10="","",IF(I10="Pagado","Pagado",IF(E10<TODAY(),"Atrasado",IF(E10<=EOMONTH(TODAY(),0),"Este mes","Pendiente")))) | M10: =IF(OR($A10="",I10="Pagado"),"",HYPERLINK("https://wa.me/"&IF(INDEX('Préstamos'!$C$2:$C$101,MATCH($A10,'Préstamos'!$A$2:$A$101,0))="","","51"&SUBSTITUTE(INDEX('Préstamos'!$C$2:$C$101,MATCH($A10,'Préstamos'!$A$2:$A$101,0))," ",""))&"?text="&SUBSTITUTE("Hola "&B10&", te recuerdo que tu cuota de S/ "&H10&IF(E10<TODAY()," vencio el "," vence el ")&TEXT(E10,"dd/mm")&". Gracias!"," ","%20"),"WhatsApp"))
A11: 3 | B11: =IF($A11="","",INDEX('Préstamos'!$B$2:$B$101,MATCH($A11,'Préstamos'!$A$2:$A$101,0))) | C11: 4 | D11: Normal | E11: 46386 | F11: =IF($A11="","",IF(D11="Solo interés",0,IF(AND(D11<>"Solo interés",C11=INDEX('Préstamos'!$G$2:$G$101,MATCH($A11,'Préstamos'!$A$2:$A$101,0))),INDEX('Préstamos'!$D$2:$D$101,MATCH($A11,'Préstamos'!$A$2:$A$101,0))-INDEX('Préstamos'!$J$2:$J$101,MATCH($A11,'Préstamos'!$A$2:$A$101,0))*(INDEX('Préstamos'!$G$2:$G$101,MATCH($A11,'Préstamos'!$A$2:$A$101,0))-1),INDEX('Préstamos'!$J$2:$J$101,MATCH($A11,'Préstamos'!$A$2:$A$101,0))))) | G11: =IF($A11="","",IF(AND(D11<>"Solo interés",C11=INDEX('Préstamos'!$G$2:$G$101,MATCH($A11,'Préstamos'!$A$2:$A$101,0))),INDEX('Préstamos'!$I$2:$I$101,MATCH($A11,'Préstamos'!$A$2:$A$101,0))-INDEX('Préstamos'!$K$2:$K$101,MATCH($A11,'Préstamos'!$A$2:$A$101,0))*(INDEX('Préstamos'!$G$2:$G$101,MATCH($A11,'Préstamos'!$A$2:$A$101,0))-1),INDEX('Préstamos'!$K$2:$K$101,MATCH($A11,'Préstamos'!$A$2:$A$101,0)))) | H11: =IF($A11="","",F11+G11) | I11: Pendiente | K11: =IF(OR($A11="",I11="Pagado"),"",MAX(0,TODAY()-E11)) | L11: =IF($A11="","",IF(I11="Pagado","Pagado",IF(E11<TODAY(),"Atrasado",IF(E11<=EOMONTH(TODAY(),0),"Este mes","Pendiente")))) | M11: =IF(OR($A11="",I11="Pagado"),"",HYPERLINK("https://wa.me/"&IF(INDEX('Préstamos'!$C$2:$C$101,MATCH($A11,'Préstamos'!$A$2:$A$101,0))="","","51"&SUBSTITUTE(INDEX('Préstamos'!$C$2:$C$101,MATCH($A11,'Préstamos'!$A$2:$A$101,0))," ",""))&"?text="&SUBSTITUTE("Hola "&B11&", te recuerdo que tu cuota de S/ "&H11&IF(E11<TODAY()," vencio el "," vence el ")&TEXT(E11,"dd/mm")&". Gracias!"," ","%20"),"WhatsApp"))
B12: =IF($A12="","",INDEX('Préstamos'!$B$2:$B$101,MATCH($A12,'Préstamos'!$A$2:$A$101,0))) | F12: =IF($A12="","",IF(D12="Solo interés",0,IF(AND(D12<>"Solo interés",C12=INDEX('Préstamos'!$G$2:$G$101,MATCH($A12,'Préstamos'!$A$2:$A$101,0))),INDEX('Préstamos'!$D$2:$D$101,MATCH($A12,'Préstamos'!$A$2:$A$101,0))-INDEX('Préstamos'!$J$2:$J$101,MATCH($A12,'Préstamos'!$A$2:$A$101,0))*(INDEX('Préstamos'!$G$2:$G$101,MATCH($A12,'Préstamos'!$A$2:$A$101,0))-1),INDEX('Préstamos'!$J$2:$J$101,MATCH($A12,'Préstamos'!$A$2:$A$101,0))))) | G12: =IF($A12="","",IF(AND(D12<>"Solo interés",C12=INDEX('Préstamos'!$G$2:$G$101,MATCH($A12,'Préstamos'!$A$2:$A$101,0))),INDEX('Préstamos'!$I$2:$I$101,MATCH($A12,'Préstamos'!$A$2:$A$101,0))-INDEX('Préstamos'!$K$2:$K$101,MATCH($A12,'Préstamos'!$A$2:$A$101,0))*(INDEX('Préstamos'!$G$2:$G$101,MATCH($A12,'Préstamos'!$A$2:$A$101,0))-1),INDEX('Préstamos'!$K$2:$K$101,MATCH($A12,'Préstamos'!$A$2:$A$101,0)))) | H12: =IF($A12="","",F12+G12) | K12: =IF(OR($A12="",I12="Pagado"),"",MAX(0,TODAY()-E12)) | L12: =IF($A12="","",IF(I12="Pagado","Pagado",IF(E12<TODAY(),"Atrasado",IF(E12<=EOMONTH(TODAY(),0),"Este mes","Pendiente")))) | M12: =IF(OR($A12="",I12="Pagado"),"",HYPERLINK("https://wa.me/"&IF(INDEX('Préstamos'!$C$2:$C$101,MATCH($A12,'Préstamos'!$A$2:$A$101,0))="","","51"&SUBSTITUTE(INDEX('Préstamos'!$C$2:$C$101,MATCH($A12,'Préstamos'!$A$2:$A$101,0))," ",""))&"?text="&SUBSTITUTE("Hola "&B12&", te recuerdo que tu cuota de S/ "&H12&IF(E12<TODAY()," vencio el "," vence el ")&TEXT(E12,"dd/mm")&". Gracias!"," ","%20"),"WhatsApp"))
B13: =IF($A13="","",INDEX('Préstamos'!$B$2:$B$101,MATCH($A13,'Préstamos'!$A$2:$A$101,0))) | F13: =IF($A13="","",IF(D13="Solo interés",0,IF(AND(D13<>"Solo interés",C13=INDEX('Préstamos'!$G$2:$G$101,MATCH($A13,'Préstamos'!$A$2:$A$101,0))),INDEX('Préstamos'!$D$2:$D$101,MATCH($A13,'Préstamos'!$A$2:$A$101,0))-INDEX('Préstamos'!$J$2:$J$101,MATCH($A13,'Préstamos'!$A$2:$A$101,0))*(INDEX('Préstamos'!$G$2:$G$101,MATCH($A13,'Préstamos'!$A$2:$A$101,0))-1),INDEX('Préstamos'!$J$2:$J$101,MATCH($A13,'Préstamos'!$A$2:$A$101,0))))) | G13: =IF($A13="","",IF(AND(D13<>"Solo interés",C13=INDEX('Préstamos'!$G$2:$G$101,MATCH($A13,'Préstamos'!$A$2:$A$101,0))),INDEX('Préstamos'!$I$2:$I$101,MATCH($A13,'Préstamos'!$A$2:$A$101,0))-INDEX('Préstamos'!$K$2:$K$101,MATCH($A13,'Préstamos'!$A$2:$A$101,0))*(INDEX('Préstamos'!$G$2:$G$101,MATCH($A13,'Préstamos'!$A$2:$A$101,0))-1),INDEX('Préstamos'!$K$2:$K$101,MATCH($A13,'Préstamos'!$A$2:$A$101,0)))) | H13: =IF($A13="","",F13+G13) | K13: =IF(OR($A13="",I13="Pagado"),"",MAX(0,TODAY()-E13)) | L13: =IF($A13="","",IF(I13="Pagado","Pagado",IF(E13<TODAY(),"Atrasado",IF(E13<=EOMONTH(TODAY(),0),"Este mes","Pendiente")))) | M13: =IF(OR($A13="",I13="Pagado"),"",HYPERLINK("https://wa.me/"&IF(INDEX('Préstamos'!$C$2:$C$101,MATCH($A13,'Préstamos'!$A$2:$A$101,0))="","","51"&SUBSTITUTE(INDEX('Préstamos'!$C$2:$C$101,MATCH($A13,'Préstamos'!$A$2:$A$101,0))," ",""))&"?text="&SUBSTITUTE("Hola "&B13&", te recuerdo que tu cuota de S/ "&H13&IF(E13<TODAY()," vencio el "," vence el ")&TEXT(E13,"dd/mm")&". Gracias!"," ","%20"),"WhatsApp"))
B14: =IF($A14="","",INDEX('Préstamos'!$B$2:$B$101,MATCH($A14,'Préstamos'!$A$2:$A$101,0))) | F14: =IF($A14="","",IF(D14="Solo interés",0,IF(AND(D14<>"Solo interés",C14=INDEX('Préstamos'!$G$2:$G$101,MATCH($A14,'Préstamos'!$A$2:$A$101,0))),INDEX('Préstamos'!$D$2:$D$101,MATCH($A14,'Préstamos'!$A$2:$A$101,0))-INDEX('Préstamos'!$J$2:$J$101,MATCH($A14,'Préstamos'!$A$2:$A$101,0))*(INDEX('Préstamos'!$G$2:$G$101,MATCH($A14,'Préstamos'!$A$2:$A$101,0))-1),INDEX('Préstamos'!$J$2:$J$101,MATCH($A14,'Préstamos'!$A$2:$A$101,0))))) | G14: =IF($A14="","",IF(AND(D14<>"Solo interés",C14=INDEX('Préstamos'!$G$2:$G$101,MATCH($A14,'Préstamos'!$A$2:$A$101,0))),INDEX('Préstamos'!$I$2:$I$101,MATCH($A14,'Préstamos'!$A$2:$A$101,0))-INDEX('Préstamos'!$K$2:$K$101,MATCH($A14,'Préstamos'!$A$2:$A$101,0))*(INDEX('Préstamos'!$G$2:$G$101,MATCH($A14,'Préstamos'!$A$2:$A$101,0))-1),INDEX('Préstamos'!$K$2:$K$101,MATCH($A14,'Préstamos'!$A$2:$A$101,0)))) | H14: =IF($A14="","",F14+G14) | K14: =IF(OR($A14="",I14="Pagado"),"",MAX(0,TODAY()-E14)) | L14: =IF($A14="","",IF(I14="Pagado","Pagado",IF(E14<TODAY(),"Atrasado",IF(E14<=EOMONTH(TODAY(),0),"Este mes","Pendiente")))) | M14: =IF(OR($A14="",I14="Pagado"),"",HYPERLINK("https://wa.me/"&IF(INDEX('Préstamos'!$C$2:$C$101,MATCH($A14,'Préstamos'!$A$2:$A$101,0))="","","51"&SUBSTITUTE(INDEX('Préstamos'!$C$2:$C$101,MATCH($A14,'Préstamos'!$A$2:$A$101,0))," ",""))&"?text="&SUBSTITUTE("Hola "&B14&", te recuerdo que tu cuota de S/ "&H14&IF(E14<TODAY()," vencio el "," vence el ")&TEXT(E14,"dd/mm")&". Gracias!"," ","%20"),"WhatsApp"))
B15: =IF($A15="","",INDEX('Préstamos'!$B$2:$B$101,MATCH($A15,'Préstamos'!$A$2:$A$101,0))) | F15: =IF($A15="","",IF(D15="Solo interés",0,IF(AND(D15<>"Solo interés",C15=INDEX('Préstamos'!$G$2:$G$101,MATCH($A15,'Préstamos'!$A$2:$A$101,0))),INDEX('Préstamos'!$D$2:$D$101,MATCH($A15,'Préstamos'!$A$2:$A$101,0))-INDEX('Préstamos'!$J$2:$J$101,MATCH($A15,'Préstamos'!$A$2:$A$101,0))*(INDEX('Préstamos'!$G$2:$G$101,MATCH($A15,'Préstamos'!$A$2:$A$101,0))-1),INDEX('Préstamos'!$J$2:$J$101,MATCH($A15,'Préstamos'!$A$2:$A$101,0))))) | G15: =IF($A15="","",IF(AND(D15<>"Solo interés",C15=INDEX('Préstamos'!$G$2:$G$101,MATCH($A15,'Préstamos'!$A$2:$A$101,0))),INDEX('Préstamos'!$I$2:$I$101,MATCH($A15,'Préstamos'!$A$2:$A$101,0))-INDEX('Préstamos'!$K$2:$K$101,MATCH($A15,'Préstamos'!$A$2:$A$101,0))*(INDEX('Préstamos'!$G$2:$G$101,MATCH($A15,'Préstamos'!$A$2:$A$101,0))-1),INDEX('Préstamos'!$K$2:$K$101,MATCH($A15,'Préstamos'!$A$2:$A$101,0)))) | H15: =IF($A15="","",F15+G15) | K15: =IF(OR($A15="",I15="Pagado"),"",MAX(0,TODAY()-E15)) | L15: =IF($A15="","",IF(I15="Pagado","Pagado",IF(E15<TODAY(),"Atrasado",IF(E15<=EOMONTH(TODAY(),0),"Este mes","Pendiente")))) | M15: =IF(OR($A15="",I15="Pagado"),"",HYPERLINK("https://wa.me/"&IF(INDEX('Préstamos'!$C$2:$C$101,MATCH($A15,'Préstamos'!$A$2:$A$101,0))="","","51"&SUBSTITUTE(INDEX('Préstamos'!$C$2:$C$101,MATCH($A15,'Préstamos'!$A$2:$A$101,0))," ",""))&"?text="&SUBSTITUTE("Hola "&B15&", te recuerdo que tu cuota de S/ "&H15&IF(E15<TODAY()," vencio el "," vence el ")&TEXT(E15,"dd/mm")&". Gracias!"," ","%20"),"WhatsApp"))
B16: =IF($A16="","",INDEX('Préstamos'!$B$2:$B$101,MATCH($A16,'Préstamos'!$A$2:$A$101,0))) | F16: =IF($A16="","",IF(D16="Solo interés",0,IF(AND(D16<>"Solo interés",C16=INDEX('Préstamos'!$G$2:$G$101,MATCH($A16,'Préstamos'!$A$2:$A$101,0))),INDEX('Préstamos'!$D$2:$D$101,MATCH($A16,'Préstamos'!$A$2:$A$101,0))-INDEX('Préstamos'!$J$2:$J$101,MATCH($A16,'Préstamos'!$A$2:$A$101,0))*(INDEX('Préstamos'!$G$2:$G$101,MATCH($A16,'Préstamos'!$A$2:$A$101,0))-1),INDEX('Préstamos'!$J$2:$J$101,MATCH($A16,'Préstamos'!$A$2:$A$101,0))))) | G16: =IF($A16="","",IF(AND(D16<>"Solo interés",C16=INDEX('Préstamos'!$G$2:$G$101,MATCH($A16,'Préstamos'!$A$2:$A$101,0))),INDEX('Préstamos'!$I$2:$I$101,MATCH($A16,'Préstamos'!$A$2:$A$101,0))-INDEX('Préstamos'!$K$2:$K$101,MATCH($A16,'Préstamos'!$A$2:$A$101,0))*(INDEX('Préstamos'!$G$2:$G$101,MATCH($A16,'Préstamos'!$A$2:$A$101,0))-1),INDEX('Préstamos'!$K$2:$K$101,MATCH($A16,'Préstamos'!$A$2:$A$101,0)))) | H16: =IF($A16="","",F16+G16) | K16: =IF(OR($A16="",I16="Pagado"),"",MAX(0,TODAY()-E16)) | L16: =IF($A16="","",IF(I16="Pagado","Pagado",IF(E16<TODAY(),"Atrasado",IF(E16<=EOMONTH(TODAY(),0),"Este mes","Pendiente")))) | M16: =IF(OR($A16="",I16="Pagado"),"",HYPERLINK("https://wa.me/"&IF(INDEX('Préstamos'!$C$2:$C$101,MATCH($A16,'Préstamos'!$A$2:$A$101,0))="","","51"&SUBSTITUTE(INDEX('Préstamos'!$C$2:$C$101,MATCH($A16,'Préstamos'!$A$2:$A$101,0))," ",""))&"?text="&SUBSTITUTE("Hola "&B16&", te recuerdo que tu cuota de S/ "&H16&IF(E16<TODAY()," vencio el "," vence el ")&TEXT(E16,"dd/mm")&". Gracias!"," ","%20"),"WhatsApp"))
B17: =IF($A17="","",INDEX('Préstamos'!$B$2:$B$101,MATCH($A17,'Préstamos'!$A$2:$A$101,0))) | F17: =IF($A17="","",IF(D17="Solo interés",0,IF(AND(D17<>"Solo interés",C17=INDEX('Préstamos'!$G$2:$G$101,MATCH($A17,'Préstamos'!$A$2:$A$101,0))),INDEX('Préstamos'!$D$2:$D$101,MATCH($A17,'Préstamos'!$A$2:$A$101,0))-INDEX('Préstamos'!$J$2:$J$101,MATCH($A17,'Préstamos'!$A$2:$A$101,0))*(INDEX('Préstamos'!$G$2:$G$101,MATCH($A17,'Préstamos'!$A$2:$A$101,0))-1),INDEX('Préstamos'!$J$2:$J$101,MATCH($A17,'Préstamos'!$A$2:$A$101,0))))) | G17: =IF($A17="","",IF(AND(D17<>"Solo interés",C17=INDEX('Préstamos'!$G$2:$G$101,MATCH($A17,'Préstamos'!$A$2:$A$101,0))),INDEX('Préstamos'!$I$2:$I$101,MATCH($A17,'Préstamos'!$A$2:$A$101,0))-INDEX('Préstamos'!$K$2:$K$101,MATCH($A17,'Préstamos'!$A$2:$A$101,0))*(INDEX('Préstamos'!$G$2:$G$101,MATCH($A17,'Préstamos'!$A$2:$A$101,0))-1),INDEX('Préstamos'!$K$2:$K$101,MATCH($A17,'Préstamos'!$A$2:$A$101,0)))) | H17: =IF($A17="","",F17+G17) | K17: =IF(OR($A17="",I17="Pagado"),"",MAX(0,TODAY()-E17)) | L17: =IF($A17="","",IF(I17="Pagado","Pagado",IF(E17<TODAY(),"Atrasado",IF(E17<=EOMONTH(TODAY(),0),"Este mes","Pendiente")))) | M17: =IF(OR($A17="",I17="Pagado"),"",HYPERLINK("https://wa.me/"&IF(INDEX('Préstamos'!$C$2:$C$101,MATCH($A17,'Préstamos'!$A$2:$A$101,0))="","","51"&SUBSTITUTE(INDEX('Préstamos'!$C$2:$C$101,MATCH($A17,'Préstamos'!$A$2:$A$101,0))," ",""))&"?text="&SUBSTITUTE("Hola "&B17&", te recuerdo que tu cuota de S/ "&H17&IF(E17<TODAY()," vencio el "," vence el ")&TEXT(E17,"dd/mm")&". Gracias!"," ","%20"),"WhatsApp"))
B18: =IF($A18="","",INDEX('Préstamos'!$B$2:$B$101,MATCH($A18,'Préstamos'!$A$2:$A$101,0))) | F18: =IF($A18="","",IF(D18="Solo interés",0,IF(AND(D18<>"Solo interés",C18=INDEX('Préstamos'!$G$2:$G$101,MATCH($A18,'Préstamos'!$A$2:$A$101,0))),INDEX('Préstamos'!$D$2:$D$101,MATCH($A18,'Préstamos'!$A$2:$A$101,0))-INDEX('Préstamos'!$J$2:$J$101,MATCH($A18,'Préstamos'!$A$2:$A$101,0))*(INDEX('Préstamos'!$G$2:$G$101,MATCH($A18,'Préstamos'!$A$2:$A$101,0))-1),INDEX('Préstamos'!$J$2:$J$101,MATCH($A18,'Préstamos'!$A$2:$A$101,0))))) | G18: =IF($A18="","",IF(AND(D18<>"Solo interés",C18=INDEX('Préstamos'!$G$2:$G$101,MATCH($A18,'Préstamos'!$A$2:$A$101,0))),INDEX('Préstamos'!$I$2:$I$101,MATCH($A18,'Préstamos'!$A$2:$A$101,0))-INDEX('Préstamos'!$K$2:$K$101,MATCH($A18,'Préstamos'!$A$2:$A$101,0))*(INDEX('Préstamos'!$G$2:$G$101,MATCH($A18,'Préstamos'!$A$2:$A$101,0))-1),INDEX('Préstamos'!$K$2:$K$101,MATCH($A18,'Préstamos'!$A$2:$A$101,0)))) | H18: =IF($A18="","",F18+G18) | K18: =IF(OR($A18="",I18="Pagado"),"",MAX(0,TODAY()-E18)) | L18: =IF($A18="","",IF(I18="Pagado","Pagado",IF(E18<TODAY(),"Atrasado",IF(E18<=EOMONTH(TODAY(),0),"Este mes","Pendiente")))) | M18: =IF(OR($A18="",I18="Pagado"),"",HYPERLINK("https://wa.me/"&IF(INDEX('Préstamos'!$C$2:$C$101,MATCH($A18,'Préstamos'!$A$2:$A$101,0))="","","51"&SUBSTITUTE(INDEX('Préstamos'!$C$2:$C$101,MATCH($A18,'Préstamos'!$A$2:$A$101,0))," ",""))&"?text="&SUBSTITUTE("Hola "&B18&", te recuerdo que tu cuota de S/ "&H18&IF(E18<TODAY()," vencio el "," vence el ")&TEXT(E18,"dd/mm")&". Gracias!"," ","%20"),"WhatsApp"))
B19: =IF($A19="","",INDEX('Préstamos'!$B$2:$B$101,MATCH($A19,'Préstamos'!$A$2:$A$101,0))) | F19: =IF($A19="","",IF(D19="Solo interés",0,IF(AND(D19<>"Solo interés",C19=INDEX('Préstamos'!$G$2:$G$101,MATCH($A19,'Préstamos'!$A$2:$A$101,0))),INDEX('Préstamos'!$D$2:$D$101,MATCH($A19,'Préstamos'!$A$2:$A$101,0))-INDEX('Préstamos'!$J$2:$J$101,MATCH($A19,'Préstamos'!$A$2:$A$101,0))*(INDEX('Préstamos'!$G$2:$G$101,MATCH($A19,'Préstamos'!$A$2:$A$101,0))-1),INDEX('Préstamos'!$J$2:$J$101,MATCH($A19,'Préstamos'!$A$2:$A$101,0))))) | G19: =IF($A19="","",IF(AND(D19<>"Solo interés",C19=INDEX('Préstamos'!$G$2:$G$101,MATCH($A19,'Préstamos'!$A$2:$A$101,0))),INDEX('Préstamos'!$I$2:$I$101,MATCH($A19,'Préstamos'!$A$2:$A$101,0))-INDEX('Préstamos'!$K$2:$K$101,MATCH($A19,'Préstamos'!$A$2:$A$101,0))*(INDEX('Préstamos'!$G$2:$G$101,MATCH($A19,'Préstamos'!$A$2:$A$101,0))-1),INDEX('Préstamos'!$K$2:$K$101,MATCH($A19,'Préstamos'!$A$2:$A$101,0)))) | H19: =IF($A19="","",F19+G19) | K19: =IF(OR($A19="",I19="Pagado"),"",MAX(0,TODAY()-E19)) | L19: =IF($A19="","",IF(I19="Pagado","Pagado",IF(E19<TODAY(),"Atrasado",IF(E19<=EOMONTH(TODAY(),0),"Este mes","Pendiente")))) | M19: =IF(OR($A19="",I19="Pagado"),"",HYPERLINK("https://wa.me/"&IF(INDEX('Préstamos'!$C$2:$C$101,MATCH($A19,'Préstamos'!$A$2:$A$101,0))="","","51"&SUBSTITUTE(INDEX('Préstamos'!$C$2:$C$101,MATCH($A19,'Préstamos'!$A$2:$A$101,0))," ",""))&"?text="&SUBSTITUTE("Hola "&B19&", te recuerdo que tu cuota de S/ "&H19&IF(E19<TODAY()," vencio el "," vence el ")&TEXT(E19,"dd/mm")&". Gracias!"," ","%20"),"WhatsApp"))
B20: =IF($A20="","",INDEX('Préstamos'!$B$2:$B$101,MATCH($A20,'Préstamos'!$A$2:$A$101,0))) | F20: =IF($A20="","",IF(D20="Solo interés",0,IF(AND(D20<>"Solo interés",C20=INDEX('Préstamos'!$G$2:$G$101,MATCH($A20,'Préstamos'!$A$2:$A$101,0))),INDEX('Préstamos'!$D$2:$D$101,MATCH($A20,'Préstamos'!$A$2:$A$101,0))-INDEX('Préstamos'!$J$2:$J$101,MATCH($A20,'Préstamos'!$A$2:$A$101,0))*(INDEX('Préstamos'!$G$2:$G$101,MATCH($A20,'Préstamos'!$A$2:$A$101,0))-1),INDEX('Préstamos'!$J$2:$J$101,MATCH($A20,'Préstamos'!$A$2:$A$101,0))))) | G20: =IF($A20="","",IF(AND(D20<>"Solo interés",C20=INDEX('Préstamos'!$G$2:$G$101,MATCH($A20,'Préstamos'!$A$2:$A$101,0))),INDEX('Préstamos'!$I$2:$I$101,MATCH($A20,'Préstamos'!$A$2:$A$101,0))-INDEX('Préstamos'!$K$2:$K$101,MATCH($A20,'Préstamos'!$A$2:$A$101,0))*(INDEX('Préstamos'!$G$2:$G$101,MATCH($A20,'Préstamos'!$A$2:$A$101,0))-1),INDEX('Préstamos'!$K$2:$K$101,MATCH($A20,'Préstamos'!$A$2:$A$101,0)))) | H20: =IF($A20="","",F20+G20) | K20: =IF(OR($A20="",I20="Pagado"),"",MAX(0,TODAY()-E20)) | L20: =IF($A20="","",IF(I20="Pagado","Pagado",IF(E20<TODAY(),"Atrasado",IF(E20<=EOMONTH(TODAY(),0),"Este mes","Pendiente")))) | M20: =IF(OR($A20="",I20="Pagado"),"",HYPERLINK("https://wa.me/"&IF(INDEX('Préstamos'!$C$2:$C$101,MATCH($A20,'Préstamos'!$A$2:$A$101,0))="","","51"&SUBSTITUTE(INDEX('Préstamos'!$C$2:$C$101,MATCH($A20,'Préstamos'!$A$2:$A$101,0))," ",""))&"?text="&SUBSTITUTE("Hola "&B20&", te recuerdo que tu cuota de S/ "&H20&IF(E20<TODAY()," vencio el "," vence el ")&TEXT(E20,"dd/mm")&". Gracias!"," ","%20"),"WhatsApp"))
B21: =IF($A21="","",INDEX('Préstamos'!$B$2:$B$101,MATCH($A21,'Préstamos'!$A$2:$A$101,0))) | F21: =IF($A21="","",IF(D21="Solo interés",0,IF(AND(D21<>"Solo interés",C21=INDEX('Préstamos'!$G$2:$G$101,MATCH($A21,'Préstamos'!$A$2:$A$101,0))),INDEX('Préstamos'!$D$2:$D$101,MATCH($A21,'Préstamos'!$A$2:$A$101,0))-INDEX('Préstamos'!$J$2:$J$101,MATCH($A21,'Préstamos'!$A$2:$A$101,0))*(INDEX('Préstamos'!$G$2:$G$101,MATCH($A21,'Préstamos'!$A$2:$A$101,0))-1),INDEX('Préstamos'!$J$2:$J$101,MATCH($A21,'Préstamos'!$A$2:$A$101,0))))) | G21: =IF($A21="","",IF(AND(D21<>"Solo interés",C21=INDEX('Préstamos'!$G$2:$G$101,MATCH($A21,'Préstamos'!$A$2:$A$101,0))),INDEX('Préstamos'!$I$2:$I$101,MATCH($A21,'Préstamos'!$A$2:$A$101,0))-INDEX('Préstamos'!$K$2:$K$101,MATCH($A21,'Préstamos'!$A$2:$A$101,0))*(INDEX('Préstamos'!$G$2:$G$101,MATCH($A21,'Préstamos'!$A$2:$A$101,0))-1),INDEX('Préstamos'!$K$2:$K$101,MATCH($A21,'Préstamos'!$A$2:$A$101,0)))) | H21: =IF($A21="","",F21+G21) | K21: =IF(OR($A21="",I21="Pagado"),"",MAX(0,TODAY()-E21)) | L21: =IF($A21="","",IF(I21="Pagado","Pagado",IF(E21<TODAY(),"Atrasado",IF(E21<=EOMONTH(TODAY(),0),"Este mes","Pendiente")))) | M21: =IF(OR($A21="",I21="Pagado"),"",HYPERLINK("https://wa.me/"&IF(INDEX('Préstamos'!$C$2:$C$101,MATCH($A21,'Préstamos'!$A$2:$A$101,0))="","","51"&SUBSTITUTE(INDEX('Préstamos'!$C$2:$C$101,MATCH($A21,'Préstamos'!$A$2:$A$101,0))," ",""))&"?text="&SUBSTITUTE("Hola "&B21&", te recuerdo que tu cuota de S/ "&H21&IF(E21<TODAY()," vencio el "," vence el ")&TEXT(E21,"dd/mm")&". Gracias!"," ","%20"),"WhatsApp"))
B22: =IF($A22="","",INDEX('Préstamos'!$B$2:$B$101,MATCH($A22,'Préstamos'!$A$2:$A$101,0))) | F22: =IF($A22="","",IF(D22="Solo interés",0,IF(AND(D22<>"Solo interés",C22=INDEX('Préstamos'!$G$2:$G$101,MATCH($A22,'Préstamos'!$A$2:$A$101,0))),INDEX('Préstamos'!$D$2:$D$101,MATCH($A22,'Préstamos'!$A$2:$A$101,0))-INDEX('Préstamos'!$J$2:$J$101,MATCH($A22,'Préstamos'!$A$2:$A$101,0))*(INDEX('Préstamos'!$G$2:$G$101,MATCH($A22,'Préstamos'!$A$2:$A$101,0))-1),INDEX('Préstamos'!$J$2:$J$101,MATCH($A22,'Préstamos'!$A$2:$A$101,0))))) | G22: =IF($A22="","",IF(AND(D22<>"Solo interés",C22=INDEX('Préstamos'!$G$2:$G$101,MATCH($A22,'Préstamos'!$A$2:$A$101,0))),INDEX('Préstamos'!$I$2:$I$101,MATCH($A22,'Préstamos'!$A$2:$A$101,0))-INDEX('Préstamos'!$K$2:$K$101,MATCH($A22,'Préstamos'!$A$2:$A$101,0))*(INDEX('Préstamos'!$G$2:$G$101,MATCH($A22,'Préstamos'!$A$2:$A$101,0))-1),INDEX('Préstamos'!$K$2:$K$101,MATCH($A22,'Préstamos'!$A$2:$A$101,0)))) | H22: =IF($A22="","",F22+G22) | K22: =IF(OR($A22="",I22="Pagado"),"",MAX(0,TODAY()-E22)) | L22: =IF($A22="","",IF(I22="Pagado","Pagado",IF(E22<TODAY(),"Atrasado",IF(E22<=EOMONTH(TODAY(),0),"Este mes","Pendiente")))) | M22: =IF(OR($A22="",I22="Pagado"),"",HYPERLINK("https://wa.me/"&IF(INDEX('Préstamos'!$C$2:$C$101,MATCH($A22,'Préstamos'!$A$2:$A$101,0))="","","51"&SUBSTITUTE(INDEX('Préstamos'!$C$2:$C$101,MATCH($A22,'Préstamos'!$A$2:$A$101,0))," ",""))&"?text="&SUBSTITUTE("Hola "&B22&", te recuerdo que tu cuota de S/ "&H22&IF(E22<TODAY()," vencio el "," vence el ")&TEXT(E22,"dd/mm")&". Gracias!"," ","%20"),"WhatsApp"))
